Workbook

Sheet Cómo se usa
B2: INSTRUMENTO DE EXPEDIENTE DE IDENTIFICACIÓN
B6: Curso–taller PLD/FT · Actividades Vulnerables · GMC360 · 360Educa
B7: 18 de agosto de 2026 · Documento de trabajo. Sin valor de asesoría legal para un caso concreto.
B10: PARA QUÉ SIRVE
B11: Este archivo arma el expediente único de identificación de UN cliente y te dice, al final, cuántos requisitos te faltan. No es un formato oficial: es el índice del expediente que la autoridad puede pedirte, construido renglón por renglón sobre el ACUERDO 115/2026.
B13: CÓMO SE LLENA
B14: 1. Ve a la hoja «Instrumento» y elige el tipo de cliente en la celda amarilla. Sólo esa celda manda.
B15: 2. La columna «¿Aplica?» se enciende sola. Filtra por «Sí» y trabaja únicamente esos renglones.
B16: 3. Contesta la columna «¿Lo tengo?» con Sí, Parcial, No o No aplica. Es la única columna que capturas.
B17: 4. Anota en «Dónde está» la ruta, la carpeta o el nombre del archivo. Un expediente que nadie encuentra no existe.
B18: 5. Revisa la hoja «Mi brecha»: ahí sale tu número.
B20: LAS TRES CLASES DE REQUISITO
... B36: Fuente: ACUERDO 115/2026, DOF 7 de agosto de 2026 · Reglas de Carácter General de la LFPIORPI · Anexos 3 a 8. El único texto con valor legal es el publicado en el Diario Oficial de la Federación.

Sheet Instrumento
A1: INSTRUMENTO DE EXPEDIENTE DE IDENTIFICACIÓN · RCG 12
A3: Tipo de cliente: | B3: Persona moral mexicana | E3: ← Elige aquí. Es la única celda que cambia el filtro. | G3: Cliente / operación:
A5: Tipo de cliente | B5: ¿Aplica? | C5: Numeral | D5: Clase | E5: Requisito | F5: Fundamento | G5: Novedad del ACUERDO 115/2026 | H5: ¿Lo tengo? | I5: Dónde está / qué falta
A6: Persona física mexicana o residente | B6: =IF(OR($A6=$B$3,$A6="Beneficiario Controlador"),"Sí","—") -> — | C6: a) i) | D6: Dato | E6: Primer apellido, segundo apellido y nombre(s), sin abreviaturas o, en caso de ser extranjero, los apellidos completos que correspondan y nombre (s); | F6: RCG 12 fr. I · Anexo 3, inciso a) i)
A7: Persona física mexicana o residente | B7: =IF(OR($A7=$B$3,$A7="Beneficiario Controlador"),"Sí","—") -> — | C7: a) ii) | D7: Dato | E7: Fecha de nacimiento; | F7: RCG 12 fr. I · Anexo 3, inciso a) ii)
A8: Persona física mexicana o residente | B8: =IF(OR($A8=$B$3,$A8="Beneficiario Controlador"),"Sí","—") -> — | C8: a) iii) | D8: Dato | E8: País de nacimiento; | F8: RCG 12 fr. I · Anexo 3, inciso a) iii)
A9: Persona física mexicana o residente | B9: =IF(OR($A9=$B$3,$A9="Beneficiario Controlador"),"Sí","—") -> — | C9: a) iv) | D9: Dato | E9: País de nacionalidad; | F9: RCG 12 fr. I · Anexo 3, inciso a) iv)
A10: Persona física mexicana o residente | B10: =IF(OR($A10=$B$3,$A10="Beneficiario Controlador"),"Sí","—") -> — | C10: a) v) | D10: Dato | E10: Actividad, ocupación, profesión, actividad o giro del negocio al que se dedique el Cliente o Usuaria, para los casos en que se establezca una Relación de negocios; | F10: RCG 12 fr. I · Anexo 3, inciso a) v)
A11: Persona física mexicana o residente | B11: =IF(OR($A11=$B$3,$A11="Beneficiario Controlador"),"Sí","—") -> — | C11: a) vi) | D11: Dato | E11: Domicilio en el lugar de residencia, compuesto de los siguientes datos: nombre de la calle, avenida o vía de que se trate, debidamente especificada; número exterior y, en su caso, interior; colonia o urbanización; demarcación territorial, municipio o demarcación política similar que corresponda, en su caso; ciudad o población, entidad federativa, estado, provincia, departamento o demarcación política similar que corresponda, en su caso; código postal y país; | F11: RCG 12 fr. I · Anexo 3, inciso a) vi)
A12: Persona física mexicana o residente | B12: =IF(OR($A12=$B$3,$A12="Beneficiario Controlador"),"Sí","—") -> — | C12: a) vii) | D12: Dato | E12: Número(s) de teléfono en que se pueda localizar, incluida la clave de larga distancia y, en su caso, extensión, cuando cuenten con aquél; | F12: RCG 12 fr. I · Anexo 3, inciso a) vii)
A13: Persona física mexicana o residente | B13: =IF(OR($A13=$B$3,$A13="Beneficiario Controlador"),"Sí","—") -> — | C13: a) viii) | D13: Dato | E13: Correo electrónico, en su caso; | F13: RCG 12 fr. I · Anexo 3, inciso a) viii)
A14: Persona física mexicana o residente | B14: =IF(OR($A14=$B$3,$A14="Beneficiario Controlador"),"Sí","—") -> — | C14: a) ix) | D14: Dato | E14: Clave Única de Registro de Población y la clave del Registro Federal de Contribuyentes, cuando cuente con ellas, y | F14: RCG 12 fr. I · Anexo 3, inciso a) ix)
A15: Persona física mexicana o residente | B15: =IF(OR($A15=$B$3,$A15="Beneficiario Controlador"),"Sí","—") -> — | C15: a) x) | D15: Dato | E15: Datos de la identificación con la que se identificó, consistentes en: nombre de la identificación; autoridad que la emite, y número de la misma. | F15: RCG 12 fr. I · Anexo 3, inciso a) x)
A16: Persona física mexicana o residente | B16: =IF(OR($A16=$B$3,$A16="Beneficiario Controlador"),"Sí","—") -> — | C16: a) párrafo final | D16: Dato | E16: Adicionalmente, tratándose de personas que tengan su lugar de residencia en el extranjero y a la vez cuenten con domicilio en territorio nacional en donde puedan recibir correspondencia dirigida a ellas, se deberá asentar en el expediente los datos relativos a dicho domicilio, con los mismos elementos que los contemplados en el numeral vi) anterior. | F16: RCG 12 fr. I · Anexo 3, inciso a) párrafo final
A17: Persona física mexicana o residente | B17: =IF(OR($A17=$B$3,$A17="Beneficiario Controlador"),"Sí","—") -> — | C17: b) i) | D17: Documento | E17: Identificación, que deberá ser, en todo caso, un documento original oficial emitido por autoridad competente, vigente o que la fecha de vencimiento, al momento de su presentación, no sea mayor a dos años, que contenga la fotografía, firma y, en su caso, domicilio del propio Cliente o Usuaria. | F17: RCG 12 fr. I · Anexo 3, inciso b) i)
A18: Persona física mexicana o residente | B18: =IF(OR($A18=$B$3,$A18="Beneficiario Controlador"),"Sí","—") -> — | C18: b) i) párrafo 2 | D18: Documento | E18: Para efectos de lo dispuesto por este numeral, se considerarán como documentos válidos de identificación la credencial para votar expedida por el Instituto Nacional Electoral, así como cualquier identificación vigente, excepto la cédula profesional, o que la fecha de vencimiento, al momento de su presentación, no sea mayor a dos años con fotografía y firma, emitida por autoridades mexicanas federales, estatales o municipales, y las demás que, en su caso, apruebe la UIF. Asimismo, respecto de las personas físicas de nacionalidad extranjera, se considerarán como documentos válidos de identificación, además de los anteriormente referidos en este párrafo, el pasaporte o la documentación expedida por el Instituto Nacional de Migración que acredite su condición de estancia en el país; | F18: RCG 12 fr. I · Anexo 3, inciso b) i) párrafo 2 | G18: Se excluye expresamente la cédula profesional como identificación válida.
A19: Persona física mexicana o residente | B19: =IF(OR($A19=$B$3,$A19="Beneficiario Controlador"),"Sí","—") -> — | C19: b) ii) | D19: Documento | E19: Constancia de la Clave Única de Registro de Población, expedida por la Secretaría de Gobernación o Cédula de Identificación Fiscal expedida por el SAT, cuando el Cliente o Usuaria cuente con ellas; No será necesario presentar la constancia de la Clave Única de Registro de Población si esta aparece en otro documento o identificación oficial. | F19: RCG 12 fr. I · Anexo 3, inciso b) ii) | G19: Simplificación real: se elimina la constancia de CURP cuando la CURP consta en otra identificación (p. ej. la credencial del INE).
A20: Persona física mexicana o residente | B20: =IF(OR($A20=$B$3,$A20="Beneficiario Controlador"),"Sí","—") -> — | C20: b) iii) | D20: Documento | E20: Comprobante que acredite el domicilio, cuando el domicilio manifestado por el Cliente o Usuaria de quien realice la Actividad Vulnerable no coincida con el de la identificación o ésta no lo contenga. En este supuesto, será necesario que quien realice la Actividad Vulnerable recabe e integre al expediente respectivo copia de un documento que acredite el domicilio del Cliente o Usuaria, que podrá ser algún recibo de pago por servicios domiciliados o estados de cuenta bancarios, todos ellos con una antigüedad no mayor a tres meses a su fecha de emisión, o el contrato de arrendamiento vigente a la fecha de presentación por el Cliente o Usuaria y registrado ante la autoridad fiscal competente, la Constancia de inscripción en el Registro Federal de Contribuyentes, así como los demás que, en su caso, apruebe la UIF; | F20: RCG 12 fr. I · Anexo 3, inciso b) iii)
A21: Persona física mexicana o residente | B21: =IF(OR($A21=$B$3,$A21="Beneficiario Controlador"),"Sí","—") -> — | C21: b) iv) | D21: Constancia | E21: Constancia por la que se acredite que quien realice la Actividad Vulnerable solicitó a su Cliente o Usuaria, información acerca de si tiene conocimiento de la existencia del Beneficiario Controlador, la cual deberá estar firmada por el Cliente o Usuaria de manera autógrafa o bien, mediante Firma Electrónica. | F21: RCG 12 fr. I · Anexo 3, inciso b) iv) | G21: Dos cambios sustantivos: (1) Dueño Beneficiario pasa a Beneficiario Controlador; (2) se admite Firma Electrónica además de la autógrafa.
A22: Persona física mexicana o residente | B22: =IF(OR($A22=$B$3,$A22="Beneficiario Controlador"),"Sí","—") -> — | C22: b) iv) párrafo 2 | D22: Constancia | E22: En el supuesto en que la persona física manifieste que sí tiene conocimiento de la existencia del Beneficiario Controlador, quien realice la Actividad Vulnerable deberá identificarlo de conformidad a lo dispuesto en la fracción VII del artículo 12 de las presentes reglas, cuando dicho Cliente o Usuaria cuente con dicha información, y | F22: RCG 12 fr. I · Anexo 3, inciso b) iv) párrafo 2 | G22: Cambio de figura (BC) y de redacción. Se conserva el condicionante “cuando cuente con dicha información”.
A23: Persona física mexicana o residente | B23: =IF(OR($A23=$B$3,$A23="Beneficiario Controlador"),"Sí","—") -> — | C23: b) v) | D23: Documento | E23: Carta poder o copia certificada del documento expedido por fedatario público, según corresponda, para el caso en que la persona física actúe como apoderado de otra persona, las cuales deberán cumplir los términos establecidos en la legislación común, a fin de que se acrediten las facultades conferidas al apoderado, así como copia de una identificación oficial y comprobante de domicilio de este, que cumplan con los requisitos señalados en este Anexo respecto de dichos documentos, con independencia de los datos y documentos relativos al poderdante. | F23: RCG 12 fr. I · Anexo 3, inciso b) v)
A24: Persona moral mexicana | B24: =IF(OR($A24=$B$3,$A24="Beneficiario Controlador"),"Sí","—") -> Sí | C24: a) i) | D24: Dato | E24: Denominación o razón social; | F24: RCG 12 fr. II · Anexo 4, inciso a) i)
A25: Persona moral mexicana | B25: =IF(OR($A25=$B$3,$A25="Beneficiario Controlador"),"Sí","—") -> Sí | C25: a) ii) | D25: Dato | E25: Fecha de constitución; | F25: RCG 12 fr. II · Anexo 4, inciso a) ii)
A26: Persona moral mexicana | B26: =IF(OR($A26=$B$3,$A26="Beneficiario Controlador"),"Sí","—") -> Sí | C26: a) iii) | D26: Dato | E26: País de nacionalidad; | F26: RCG 12 fr. II · Anexo 4, inciso a) iii)
A27: Persona moral mexicana | B27: =IF(OR($A27=$B$3,$A27="Beneficiario Controlador"),"Sí","—") -> Sí | C27: a) iv) | D27: Dato | E27: Actividad, giro mercantil, actividad u objeto social para los casos en que se establezca una Relación de Negocios; | F27: RCG 12 fr. II · Anexo 4, inciso a) iv)
A28: Persona moral mexicana | B28: =IF(OR($A28=$B$3,$A28="Beneficiario Controlador"),"Sí","—") -> Sí | C28: a) v) | D28: Dato | E28: Domicilio, compuesto de los elementos siguientes: nombre de la calle, avenida o vía de que se trate, debidamente especificada; número exterior y, en su caso, interior; colonia o urbanización; demarcación territorial, municipio o demarcación política similar que corresponda, en su caso; ciudad o población, entidad federativa, estado, provincia, departamento o demarcación política similar que corresponda, en su caso; código postal y país; | F28: RCG 12 fr. II · Anexo 4, inciso a) v)
A29: Persona moral mexicana | B29: =IF(OR($A29=$B$3,$A29="Beneficiario Controlador"),"Sí","—") -> Sí | C29: a) vi) | D29: Dato | E29: Número(s) de teléfono de dicho domicilio, incluida la clave de larga distancia y, en su caso, extensión, cuando cuenten con aquél; | F29: RCG 12 fr. II · Anexo 4, inciso a) vi)
A30: Persona moral mexicana | B30: =IF(OR($A30=$B$3,$A30="Beneficiario Controlador"),"Sí","—") -> Sí | C30: a) vii) | D30: Dato | E30: Correo electrónico, en su caso; | F30: RCG 12 fr. II · Anexo 4, inciso a) vii)
A31: Persona moral mexicana | B31: =IF(OR($A31=$B$3,$A31="Beneficiario Controlador"),"Sí","—") -> Sí | C31: a) viii) | D31: Dato | E31: Clave del Registro Federal de Contribuyentes, cuando cuente con ella, y | F31: RCG 12 fr. II · Anexo 4, inciso a) viii)
A32: Persona moral mexicana | B32: =IF(OR($A32=$B$3,$A32="Beneficiario Controlador"),"Sí","—") -> Sí | C32: a) ix) | D32: Dato | E32: Nombre(s), primer y segundo apellidos o, en caso de ser extranjero, los apellidos completos que correspondan y nombre (s), sin abreviaturas, así como fecha de nacimiento, clave del Registro Federal de Contribuyentes o Clave Única de Registro de Población del representante, apoderados legales o personas que realicen el acto u operación a nombre de la persona moral de que se trate. Asimismo, deberán recabar datos de su identificación, consistentes en: nombre de la identificación; autoridad que la emite, y número de la misma; | F32: RCG 12 fr. II · Anexo 4, inciso a) ix)
A33: Persona moral mexicana | B33: =IF(OR($A33=$B$3,$A33="Beneficiario Controlador"),"Sí","—") -> Sí | C33: b) i) | D33: Documento | E33: Testimonio o copia certificada del instrumento público que acredite su constitución e inscripción en el registro público que corresponda, de acuerdo con la naturaleza de la persona moral, o de cualquier instrumento en el que consten los datos de su constitución y los de su inscripción en dicho registro, o bien, del documento que, de acuerdo con su naturaleza o el régimen que le resulte aplicable a la persona moral de que se trate, acredite su existencia. | F33: RCG 12 fr. II · Anexo 4, inciso b) i)
A34: Persona moral mexicana | B34: =IF(OR($A34=$B$3,$A34="Beneficiario Controlador"),"Sí","—") -> Sí | C34: b) i) párrafo 2 | D34: Documento | E34: En caso de que la persona moral sea de reciente constitución y, en tal virtud, no se encuentre aún inscrita en el registro público que corresponda de acuerdo con su naturaleza, quien realice la Actividad Vulnerable de que se trate deberá obtener un escrito firmado por persona legalmente facultada que acredite su personalidad en términos del instrumento público que acredite su constitución a que se refiere el inciso b) numeral iv) de este Anexo, en el que conste la obligación de llevar a cabo la inscripción respectiva y proporcionar, en su oportunidad, los datos correspondientes a quien realice la Actividad Vulnerable; | F34: RCG 12 fr. II · Anexo 4, inciso b) i) párrafo 2
... A36: Persona moral mexicana | B36: =IF(OR($A36=$B$3,$A36="Beneficiario Controlador"),"Sí","—") -> Sí | C36: b) iii) | D36: Documento | E36: Comprobante que acredite el domicilio a que se refiere el numeral v), del inciso a) anterior, que podrá ser algún recibo de pago por servicios domiciliados o estados de cuenta bancarios, todos ellos con una antigüedad no mayor a tres meses a su fecha de emisión, o el contrato de arrendamiento vigente a la fecha de presentación por el Cliente o Usuaria y registrado ante la autoridad fiscal competente, la Constancia de inscripción en el Registro Federal de Contribuyentes, así como los demás que, en su caso, apruebe la UIF; | F36: RCG 12 fr. II · Anexo 4, inciso b) iii)
A37: Persona moral mexicana | B37: =IF(OR($A37=$B$3,$A37="Beneficiario Controlador"),"Sí","—") -> Sí | C37: b) iv) | D37: Documento | E37: Testimonio o copia certificada del instrumento que contenga los poderes del representante o apoderados legales, expedido por fedatario público, cuando no estén contenidos en el instrumento público que acredite la constitución de la persona moral de que se trate, así como la identificación de cada uno de dichos representantes, apoderados legales o personas que realicen el acto u operación a nombre de dicha persona moral, que deberá ser, en todo caso, un documento original oficial emitido por autoridad competente, vigente o que la fecha de vencimiento, al momento de su presentación no sea mayor a dos años, que contenga la fotografía, firma y, en su caso, domicilio de la referida persona. Para efectos de lo dispuesto por este numeral, se considerarán como documentos válidos de identificación la credencial para votar expedida por el Instituto Nacional Electoral, así como cualquier identificación vigente, excepto la cédula profesional, o que la fecha de vencimiento, al momento de su presentación, no sea mayor a dos años con fotografía y firma, emitida por autoridades mexicanas federales, estatales o municipales, y las demás que, en su caso, apruebe la UIF. | F37: RCG 12 fr. II · Anexo 4, inciso b) iv) | G37: Se excluye expresamente la cédula profesional como identificación válida.
A38: Persona moral mexicana | B38: =IF(OR($A38=$B$3,$A38="Beneficiario Controlador"),"Sí","—") -> Sí | C38: b) iv) párrafo 2 | D38: Documento | E38: Asimismo, respecto de las personas físicas de nacionalidad extranjera, se considerarán como documentos válidos de identificación, además de los anteriormente referidos en este numeral, el pasaporte o la documentación expedida por el Instituto Nacional de Migración que acredite su condición de estancia en el país, y | F38: RCG 12 fr. II · Anexo 4, inciso b) iv) párrafo 2
A39: Persona moral mexicana | B39: =IF(OR($A39=$B$3,$A39="Beneficiario Controlador"),"Sí","—") -> Sí | C39: b) v) | D39: Constancia | E39: Quien realice la Actividad Vulnerable deberá identificar de conformidad a lo dispuesto en la fracción VII, segundo párrafo del artículo 12 de las presentes reglas, al Beneficiario Controlador. En el supuesto en que el representante o apoderados legales de la persona moral manifiesten que sí tienen conocimiento de la existencia del Dueño Beneficiario, quien realice la Actividad Vulnerable deberá identificarlo de conformidad a lo dispuesto en la fracción VII del artículo 12 de las presentes Reglas, cuando dicho Cliente o Usuario cuente con dicha información. | F39: RCG 12 fr. II · Anexo 4, inciso b) v) | G39: Sustitución total del requisito: desaparece la constancia declarativa y nace la obligación directa de identificar al Beneficiario Controlador conforme al artículo 12, fracción VII, segundo párrafo.
A40: Persona moral mexicana de derecho público | B40: =IF(OR($A40=$B$3,$A40="Beneficiario Controlador"),"Sí","—") -> — | C40: a) i) | D40: Dato | E40: Nombre de la persona moral mexicana de derecho público que corresponda; | F40: RCG 12 fr. II Bis · Anexo 4 Bis, inciso a) i)
A41: Persona moral mexicana de derecho público | B41: =IF(OR($A41=$B$3,$A41="Beneficiario Controlador"),"Sí","—") -> — | C41: a) ii) | D41: Dato | E41: Fecha de creación o de constitución; | F41: RCG 12 fr. II Bis · Anexo 4 Bis, inciso a) ii)
A42: Persona moral mexicana de derecho público | B42: =IF(OR($A42=$B$3,$A42="Beneficiario Controlador"),"Sí","—") -> — | C42: a) iii) | D42: Dato | E42: Domicilio, compuesto de los elementos siguientes: nombre de la calle, avenida o vía de que se trate, debidamente especificada; número exterior y, en su caso, interior; colonia o urbanización; demarcación territorial, municipio o demarcación política similar que corresponda, en su caso; ciudad o población, entidad federativa, estado, provincia, departamento o demarcación política similar que corresponda, en su caso; código postal y país; | F42: RCG 12 fr. II Bis · Anexo 4 Bis, inciso a) iii)
A43: Persona moral mexicana de derecho público | B43: =IF(OR($A43=$B$3,$A43="Beneficiario Controlador"),"Sí","—") -> — | C43: a) iv) | D43: Dato | E43: Número(s) de teléfono de dicho domicilio, incluida la clave de larga distancia y, en su caso, extensión, cuando cuenten con aquél; | F43: RCG 12 fr. II Bis · Anexo 4 Bis, inciso a) iv)
...

Sheet Comparativo por anexo
A1: QUÉ PIDE CADA ANEXO — MATRIZ COMPARATIVA
B3: Cada anexo redacta y numera distinto los mismos conceptos. Aquí están normalizados: hacia abajo el requisito, a la derecha el anexo, y en la celda el numeral exacto donde vive. Una celda vacía significa que ese anexo no lo pide.
B5: Requisito | C5: Clase | D5: ANEXO 3 Persona física mexicana o residente | E5: ANEXO 4 Persona moral mexicana | F5: ANEXO 4 Bis Persona moral de derecho público | G5: ANEXO 5 Persona física extranjera (visitante) | H5: ANEXO 6 Persona moral extranjera | I5: ANEXO 6 Bis Embajada, consulado, organismo int. | J5: ANEXO 7 Simplificado (Anexo 7-A) | K5: ANEXO 7 Bis Simplificado de derecho público | L5: ANEXO 8 Fideicomiso
B6: Nombre, denominación o razón social | C6: Dato | D6: a) i) | E6: a) i) | F6: a) i) | G6: a) i) | H6: a) i) | I6: a) i) | J6: a) i) | K6: a) i) | L6: a) i) del fiduciario
B7: Fecha de nacimiento, constitución o creación | C7: Dato | D7: a) ii) | E7: a) ii) | F7: a) ii) | G7: a) ii) | H7: a) ii) | I7: a) ii) o RFC | J7: a) iii) o RFC | K7: a) ii) o RFC | L7: —
B8: País de nacimiento | C8: Dato | D8: a) iii) | E8: — | F8: — | G8: a) iii) | H8: — | I8: — | J8: — | K8: — | L8: —
B9: País de nacionalidad | C9: Dato | D9: a) iv) | E9: a) iii) | F9: — | G9: a) iv) | H9: a) iii) | I9: — | J9: — | K9: — | L9: —
B10: Actividad, ocupación u objeto social — sólo si hay Relación de negocios | C10: Dato | D10: a) v) | E10: a) iv) | F10: — | G10: a) v) | H10: a) iv) | I10: — | J10: a) ii) | K10: — | L10: —
B11: Domicilio | C11: Dato | D11: a) vi) | E11: a) v) | F11: a) iii) | G11: a) vi) | H11: a) vi) | I11: a) iii) | J11: a) iv) | K11: a) iii) | L11: —
B12: Teléfono | C12: Dato | D12: a) vii) | E12: a) vi) | F12: a) iv) | G12: — | H12: a) vii) | I12: a) iv) | J12: a) v) | K12: — | L12: —
B13: Correo electrónico | C13: Dato | D13: a) viii) | E13: a) vii) | F13: a) v) | G13: — | H13: a) viii) | I13: a) v) | J13: a) vi) | K13: — | L13: —
B14: CURP y RFC (o número de identificación fiscal extranjero) | C14: Dato | D14: a) ix) | E14: a) viii) | F14: a) vi) | G14: — | H14: a) v) | I14: a) ii) | J14: a) iii) | K14: a) ii) | L14: a) iii)
B15: Datos de la identificación con la que se identificó | C15: Dato | D15: a) x) | E15: — | F15: — | G15: a) vii) | H15: — | I15: — | J15: — | K15: — | L15: —
B16: Domicilio en México cuando reside en el extranjero | C16: Dato | D16: a) párr. final | E16: — | F16: — | G16: a) párr. final | H16: — | I16: — | J16: — | K16: — | L16: —
... B27: Beneficiario Controlador | C27: Constancia | D27: b) iv) CONSTANCIA | E27: b) v) IDENTIFICAR | F27: — | G27: b) iv) CONSTANCIA | H27: b) v) IDENTIFICAR | I27: DEROGADA | J27: — | K27: — | L27: b) iv) IDENTIFICAR
B28: Conceptos que pide este anexo | D28: =COUNTIFS(D6:D27,"<>—",D6:D27,"<>DEROGADA") -> 16 | E28: =COUNTIFS(E6:E27,"<>—",E6:E27,"<>DEROGADA") -> 14 | F28: =COUNTIFS(F6:F27,"<>—",F6:F27,"<>DEROGADA") -> 11 | G28: =COUNTIFS(G6:G27,"<>—",G6:G27,"<>DEROGADA") -> 14 | H28: =COUNTIFS(H6:H27,"<>—",H6:H27,"<>DEROGADA") -> 14 | I28: =COUNTIFS(I6:I27,"<>—",I6:I27,"<>DEROGADA") -> 11 | J28: =COUNTIFS(J6:J27,"<>—",J6:J27,"<>DEROGADA") -> 8 | K28: =COUNTIFS(K6:K27,"<>—",K6:K27,"<>DEROGADA") -> 5 | L28: =COUNTIFS(L6:L27,"<>—",L6:L27,"<>DEROGADA") -> 8
B30: CÓMO SE LEE
B31: El numeral (por ejemplo «a) iii)») | C31: Ese anexo sí lo pide, y ése es su numeral exacto dentro del anexo.
B32: Una raya | C32: Ese anexo no pide ese concepto.
B33: IDENTIFICAR — verde | C33: Anexos 4, 6 y 8. Ya no basta la declaración del cliente: hay que identificar al Beneficiario Controlador.
B34: CONSTANCIA — ámbar | C34: Anexos 3 y 5. Se conserva la constancia declarativa firmada por el cliente, ahora también con Firma Electrónica.
B35: DEROGADA — rojo | C35: Anexo 6 Bis. Se eliminó la constancia para embajadas, consulados y organismos internacionales.
B37: Fuente: ACUERDO 115/2026, DOF 7 de agosto de 2026 · Anexos 3 a 8 de las Reglas de Carácter General. Los conceptos fueron normalizados por GMC360 porque cada anexo los redacta y numera distinto; el numeral de cada celda sí es literal. El único texto con valor legal es el publicado en el DOF.

Sheet Casos difíciles
A1: LOS OCHO CASOS QUE ROMPEN EL EXPEDIENTE
A3: El expediente fácil lo arma cualquiera. Estos son los ocho casos en que se tuerce — y los ocho ya tienen respuesta en el texto, sólo que vive en los artículos de en medio que casi nadie lee.
A5: # | B5: Si te pasa esto… | C5: Qué dice la norma que hagas | D5: Fundamento | E5: ¿Me pasa? | F5: Nota
A6: 1 | B6: El cliente se niega a darte la información o los documentos | C6: PRIMERO: te abstienes de llevar a cabo el acto u operación, «sin responsabilidad alguna» (L 21). No es que puedas negarte: es que debes, y la Ley te cubre. Deja constancia escrita de la negativa y de la fecha. Y ADEMÁS, si de esa negativa nace sospecha sobre el origen o destino de los recursos, hay aviso de 24 horas — aunque no haya contrato y aunque sólo cuentes con los datos de quien INTENTÓ la operación (L 18 fr. VI, que dice «incluso si el acto u operación no se celebró», y R 7 Bis). OJO CON EL LÍMITE: negarse a dar papeles no es lo mismo que sospechar del origen del dinero. Confundirlos genera avisos basura. La pregunta correcta es por qué se negó, y si eso te hace sospechar. | D6: L 21 · L 18 fr. VI · R 7 Bis
A7: 2 | B7: El documento de identificación trae tachaduras o enmendaduras | C7: Recabas otro medio de identificación. Si no lo hay, solicitas DOS referencias bancarias o comerciales y DOS referencias personales, y verificas esos datos con quienes las suscriben ANTES de establecer la relación o celebrar la operación. | D7: RCG 12
A8: 3 | B8: Tienes indicios de que el cliente actúa por cuenta de otra persona y no lo declaró | C8: El artículo 22 fija qué hacer cuando cuentas con información basada en indicios o hechos de que tu cliente actúa por cuenta de otro sin haberlo manifestado. | D8: RCG 22
A9: 4 | B9: Ese cliente ya fue identificado por otra empresa de tu grupo empresarial | C9: El expediente puede integrarlo y conservarlo cualquiera de las personas morales del grupo, y pueden intercambiarse los datos para una nueva operación — pero con tres condiciones, y una es que quien lo conserve observe los criterios de identificación de quien realiza la actividad. No es automático. | D9: RCG 14
A10: 5 | B10: Realizas actos u operaciones a nombre de los trabajadores o del personal de tu cliente | C10: Debes convenir POR ESCRITO con el cliente solicitante su obligación de mantener ese expediente a tu disposición para consulta y de proporcionártelo cuando lo requieras. | D10: RCG 16
A11: 6 | B11: Toda la operación es a distancia y nunca ves al cliente en persona | C11: Se admiten medios electrónicos, ópticos o de cualquier otra tecnología — pero el expediente de identificación se integra PREVIAMENTE. Si operas primero y armas después, incumpliste aunque tengas todo. | D11: RCG 18
A12: 7 | B12: Tu cliente califica como de riesgo bajo, o como de riesgo medio | C12: Bajo riesgo: medidas simplificadas del RCG 17, con la obligación de solicitar los documentos en original o copia certificada por fedatario, y sólo si además tu entidad quedó en bajo riesgo conforme al Art. 15 del Reglamento: son dos condiciones acumulativas. Riesgo medio: régimen propio del 17 Bis. Y si el cliente se aparta de los criterios de bajo riesgo, integras el expediente completo. | D12: RCG 17 y 17 Bis
A13: 8 | B13: Eres fedatario y en la fe pública no hay Relación de negocios | C13: Identificas a quien comparece al momento del acto, y tienes por cumplida la obligación del artículo 12 si la información y documentación requerida ya consta en el instrumento. El 13 Bis regula el caso de servicios de fe pública al Poder Judicial. | D13: RCG 13 y 13 Bis
B15: Y el caso que no está aquí
B16: Si tu situación no encaja en ninguno de los ocho, no la inventes ni la fuerces: anótala en la columna «Nota» y llévala al curso. Las que no tengan respuesta en el texto se suman al documento de dudas del sector que va a la Dirección de Actividades Vulnerables de la UIF.
B18: Fuente: ACUERDO 115/2026, DOF 7 de agosto de 2026, y LFPIORPI vigente. Cotejado artículo por artículo. El único texto con valor legal es el publicado en el DOF.

Sheet Trazabilidad
A1: CADENA DE EVIDENCIA DE UNA OPERACIÓN
A3: Un expediente completo no basta si la operación no se puede reconstruir de punta a punta. Estos nueve eslabones son los que permiten esa reconstrucción. Cada uno lleva el artículo que lo exige: donde no hay artículo, se dice.
A5: # | B5: Eslabón | C5: Qué tiene que existir | D5: Fundamento | E5: ¿La tengo? | F5: Dónde está
A6: 1 | B6: Expediente de identificación | C6: Integrado antes o durante el acto u operación, o antes de establecer la Relación de negocios. | D6: RCG 12 · L 18 fr. I
A7: 2 | B7: Actividad u ocupación del cliente | C7: Solicitada cuando hay Relación de negocios, apoyándose en los avisos de inscripción y actualización ante el RFC. | D7: L 18 fr. II
A8: 3 | B8: Documento del acto u operación | C8: Contrato, escritura, factura, orden o instrucción: el papel que prueba qué se pactó, cuándo y por cuánto. | D8: L 18 fr. IV — «registros que permitan la reconstrucción de operaciones en lo individual» y la correspondencia comercial
A9: 4 | B9: CFDI | C9: El comprobante fiscal de la operación, consistente con lo que declaraste. El SAT presume cierta la información que contiene. | D9: R 10 Bis, párrafo final
A10: 5 | B10: Comprobante de pago | C10: Cómo entró el dinero: transferencia, cheque, efectivo. Es lo que amarra el CFDI con la realidad. | D10: Buena práctica. No hay artículo que lo exija por separado: se sostiene en L 18 fr. IV
A11: 6 | B11: Conciliación | C11: Que el monto del contrato, el del CFDI y el del pago sean el mismo. Cuando no lo son, hay que explicar por qué y dejarlo escrito. | D11: Buena práctica de GMC360. No es requisito normativo autónomo
A12: 7 | B12: Cálculo de acumulación | C12: La suma por cliente en el periodo de hasta seis meses, para saber si se alcanzó el umbral de aviso. | D12: R 7
A13: 8 | B13: Aviso y acuse | C13: Copia del aviso, su documentación soporte y el acuse electrónico. Se conservan diez años desde la presentación. | D13: R 20
A14: 9 | B14: Resguardo | C14: Todo lo anterior, físico o electrónico, por al menos diez años contados desde la realización de la Actividad Vulnerable. Se conserva en el domicilio registrado ante la Secretaría, salvo la fracción XIV del artículo 17: esa fracción está exceptuada del domicilio, no del plazo. | D14: L 18 fr. IV, segundo párrafo
B16: Dos eslabones no son norma y están marcados como tales.
B17: El comprobante de pago y la conciliación son método de trabajo, no requisito autónomo. Se incluyen porque son lo que hace verificable el resto — y porque el artículo 21 de la Ley obliga a abstenerse de operar cuando el cliente se niega a dar la información necesaria, lo que en la práctica se decide con estos dos eslabones a la vista.

Sheet Mi brecha
A1: MI BRECHA
B3: Se calcula solo desde la hoja «Instrumento». No escribas nada en esta hoja.
B5: TU EXPEDIENTE, EN NÚMEROS
B6: Requisitos que te aplican | C6: =COUNTIF(Instrumento!$B$6:$B$116,"Sí") -> 20 | E6: Depende del tipo de cliente que elegiste.
B7: Marcados «No aplica» | C7: =COUNTIFS(Instrumento!$B$6:$B$116,"Sí",Instrumento!$H$6:$H$116,"No aplica") -> 0 | E7: Úsalo poco. Si todo es «no aplica», el resultado no te sirve.
B8: Base de medición | C8: =C6-C7 -> 20 | E8: Los que sí te tocan.
B9: Los tengo | C9: =COUNTIFS(Instrumento!$B$6:$B$116,"Sí",Instrumento!$H$6:$H$116,"Sí") -> 0
B10: Los tengo a medias | C10: =COUNTIFS(Instrumento!$B$6:$B$116,"Sí",Instrumento!$H$6:$H$116,"Parcial") -> 0 | E10: Cuentan como medio punto.
B11: No los tengo | C11: =COUNTIFS(Instrumento!$B$6:$B$116,"Sí",Instrumento!$H$6:$H$116,"No") -> 0 | E11: Ésta es tu brecha real.
B12: Sin contestar | C12: =C8-C9-C10-C11 -> 20 | E12: Si es alto, el resultado todavía no significa nada.
B14: GRADO DE INTEGRACIÓN | C14: =IF(C8=0,0,(C9+C10*0.5)/C8) -> 0 | E14: Completos más la mitad de los parciales, entre la base de medición.
B16: =IF(C12>0,"Contesta primero los "&C12&" renglones que faltan",IF(C14>=0.9,"VERDE · expediente defendible. Falta poco.",IF(C14>=0.6,"ÁMBAR · el expediente existe pero tiene huecos. Ciérralos antes del 30 de noviembre.","ROJO · el expediente no resiste una verificación. Es tu primer proyecto, antes del manual."))) -> Contesta primero los 20 renglones que faltan
B18: POR CLASE DE REQUISITO
B19: Clase | C19: Te aplican | D19: Los tienes | E19: %
B20: Dato | C20: =COUNTIFS(Instrumento!$B$6:$B$116,"Sí",Instrumento!$D$6:$D$116,"Dato") -> 13 | D20: =COUNTIFS(Instrumento!$B$6:$B$116,"Sí",Instrumento!$D$6:$D$116,"Dato",Instrumento!$H$6:$H$116,"Sí") -> 0 | E20: =IF(C20=0,"—",D20/C20) -> 0
B21: Documento | C21: =COUNTIFS(Instrumento!$B$6:$B$116,"Sí",Instrumento!$D$6:$D$116,"Documento") -> 6 | D21: =COUNTIFS(Instrumento!$B$6:$B$116,"Sí",Instrumento!$D$6:$D$116,"Documento",Instrumento!$H$6:$H$116,"Sí") -> 0 | E21: =IF(C21=0,"—",D21/C21) -> 0
B22: Constancia | C22: =COUNTIFS(Instrumento!$B$6:$B$116,"Sí",Instrumento!$D$6:$D$116,"Constancia") -> 1 | D22: =COUNTIFS(Instrumento!$B$6:$B$116,"Sí",Instrumento!$D$6:$D$116,"Constancia",Instrumento!$H$6:$H$116,"Sí") -> 0 | E22: =IF(C22=0,"—",D22/C22) -> 0
B24: LO QUE SIGUE
B25: · Los renglones en «No» son tu lista de trabajo. Tienen fecha: 30 de noviembre de 2026.
B26: · Repite este ejercicio con tu cliente más complicado, no con el más fácil. El fácil no te enseña nada.
B27: · La verificación anual de los expedientes de clientes con Relación de negocios es obligatoria — artículo 21 RCG. Este archivo es el formato con el que se hace.
B28: · El grado de riesgo de este cliente se calcula en el Módulo 8, con la Matriz y su metodología.
