Workbook

Sheet INICIO
B1: v9.0 · 1 de septiembre de 2026 · modelo de cliente de 22 factores
B2: HERRAMIENTA DE EVALUACIÓN DE RIESGO EBR · ACTIVIDADES VULNERABLES (LFPIORPI)
B3: Determina tu riesgo inherente y residual conforme a las Reglas (Cap. II Quáter y III Bis/III Ter), la Guía CNBV y GAFILAT.
B4: NOTA: trae un EJEMPLO completo precargado (una inmobiliaria, fracción V). Todo lo que está en texto azul es del ejemplo: sustitúyelo por lo tuyo.
B5: Paso 1 de 10 · Configura antes en PARÁMETROS · Sigue: A9 secciones 1 y 2 (ENR y conciliación), y luego A1
B6: CÓMO USAR
B7: 1. Abre primero PARÁMETROS: actualiza el valor de la UMA y declara tu nivel de tolerancia al riesgo. Se hace una vez al año.
B8: 2. Aquí en INICIO elige tu Actividad Vulnerable —se precargan tus umbrales— y captura los datos de tu entidad y las tres cifras de doce meses (Art. 10 Septies 2, fr. II).
B9: 3. Ve a «A9» secciones 1 y 2 ANTES de capturar nada: la Evaluación Nacional de Riesgos que tomaste en cuenta, y la conciliación de tus tres cifras contra tu mecanismo automatizado.
B10: 4. En «A1 EXPOSICION» reparte 100% entre Alto/Medio/Bajo en cada indicador y asigna los dos pesos —el del indicador y el del elemento— con su justificación escrita. En «A2» describe qué pasaría si el riesgo se materializa.
B11: 5. Revisa el inherente en «A3». En «A4 CONTROLES MINIMOS» califica las 14 obligaciones del Manual (Art. 37 Bis) y anota numeral y evidencia: sin los dos, la obligación cuenta cero. Los controles extra van en «A4 BIS».
B12: 6. Lee el residual en «A5» y el resumen en «A6». Cierra en «A8» (tolerancia, fecha de revisión y plan de acción) y en «A9» secciones 3 a 7 (aprobación, plazos y conservación).
... B14: LEYENDA
B15: Amarillo = tú capturas | C15: Verde = viene de otra hoja | D15: Negro = se calcula solo
B16: Texto azul = dato de ejemplo: sustitúyelo | C16: Gris = referencia fija: no se edita | D16: Texto rojo = aviso · Relleno azul = resultado clave
B17: PASO 1 · SELECCIONA TU ACTIVIDAD VULNERABLE
B18: Actividad Vulnerable: | C18: V - Construcción/comercialización inmuebles
B19: Fracción Art. 17: | C19: =IFERROR(INDEX(CATALOGO!$C$6:$C$35,MATCH($C$18,CATALOGO!$E$6:$E$35,0)),"")
B20: Umbral de identificación (UMA): | C20: =IFERROR(INDEX(CATALOGO!$F$6:$F$35,MATCH($C$18,CATALOGO!$E$6:$E$35,0)),"") | D20: Umbral de aviso (UMA): | E20: =IFERROR(INDEX(CATALOGO!$G$6:$G$35,MATCH($C$18,CATALOGO!$E$6:$E$35,0)),"")
B21: Umbral de identificación (MXN): | C21: =IFERROR(INDEX(CATALOGO!$H$6:$H$35,MATCH($C$18,CATALOGO!$E$6:$E$35,0)),"") | D21: Umbral de aviso (MXN): | E21: =IFERROR(INDEX(CATALOGO!$I$6:$I$35,MATCH($C$18,CATALOGO!$E$6:$E$35,0)),"")
B23: PASO 2 · DATOS DE LA ENTIDAD
B24: Denominación o razón social: | C24: Inmobiliaria Ejemplo, S.A. de C.V.
B25: Nombre corto o comercial: | C25: Inmobiliaria Ejemplo
B26: Representante / Encargado de Cumplimiento: | C26: María Ejemplo Ruiz — Representante Encargada de Cumplimiento
B27: Fecha de la evaluación: | C27: 46204
B28: Periodo analizado (inicio): | C28: 45839
B29: Periodo analizado (fin, mín. 12 meses): | C29: 46203
B31: PASO 3 · DATOS DE 12 MESES (base de la evaluación, Art. 10 Septies 2)
B32: Número total de Clientes/Usuarias: | C32: 86
B33: Número total de actos u operaciones: | C33: 112
B34: Monto total operado (MXN): | C34: 428600000
B36: Revisa y actualiza al menos cada 12 meses o al actualizarse la ENR. Conserva la documentación 10 años.
B38: ESTADO DE AVANCE — REVÍSALO ANTES DE IMPRIMIR, FIRMAR O ENTREGAR
B39: Verificación | E39: Dato | F39: Estatus
B40: Indicadores cuyo reparto Alto/Medio/Bajo no suma 100% | E40: =SUMPRODUCT(--('A1 EXPOSICION'!$G$7:$G$31="Sí"),--(ABS('A1 EXPOSICION'!$N$7:$N$31-1)>0.001)) | F40: =IF(E40=0,"OK","Corregir")
B41: Suma de los pesos de los cuatro elementos (debe ser 100%) | E41: ='A1 EXPOSICION'!$D$40 | F41: =IF(ABS(E41-1)<=0.001,"OK","Corregir")
B42: Indicadores excluidos sin justificación escrita | E42: ='A1 EXPOSICION'!$E$45 | F42: =IF(E42=0,"OK","Corregir")
B43: Obligaciones del catálogo sin calificar | E43: ='A4 CONTROLES MINIMOS'!$F$36 | F43: =IF(E43=0,"OK","Corregir")
B44: Obligaciones del catálogo en «No cumple» | E44: ='A4 CONTROLES MINIMOS'!$F$33 | F44: =IF(E44=0,"OK","Corregir")
B45: Exclusiones del catálogo sin constancia en el Manual | E45: ='A4 CONTROLES MINIMOS'!$F$34 | F45: =IF(E45=0,"OK","Corregir")
...

Sheet A1 EXPOSICION
B2: A1 · EXPOSICIÓN — Captura tu concentración de negocio (12 meses)
B3: Por cada indicador reparte el 100% entre Alto/Medio/Bajo. Calificación = qué tan riesgoso; Concentración = qué tan expuesto; Riesgo = Calif × Conc. Un indicador en «No» sale del numerador y del denominador.
B4: Paso 3 de 10 · Viene de: A9 §1 y §2 · Sigue: A2 CONSECUENCIAS
B5: OJO · La unidad del reparto cambia según el indicador: en unos el 100 % se reparte sobre el NÚMERO DE CLIENTES o de operaciones, y en otros sobre los MONTOS OPERADOS (por ejemplo tipo de moneda, monto frente a umbrales o instrumento monetario). Lee la columna «Guía» de cada renglón antes de capturar, y anota en «Justificación» sobre qué lo repartiste. | G5: GRIS = obligatorio (139 Quáter / 400 Bis): no admite «No». AMARILLO = tú decides si aplica.
B6: Elem. | C6: # | D6: Indicador | E6: Atiende | F6: Fuente | G6: Aplica | H6: Guía ALTO | I6: Guía MEDIO | J6: Guía BAJO | K6: % Alto | L6: % Medio | M6: % Bajo | N6: Suma | O6: Peso (relativo dentro del elemento) | P6: Calif. | Q6: Conc. | R6: Riesgo | S6: Justificación (del No aplica o del peso)
B7: 1 | C7: 1 | D7: Valor unitario de la operación | F7: B | G7: Sí | H7: =IFERROR(INDEX(BASE!$E:$E,MATCH(INICIO!$C$18&"-"&$C7,BASE!$A:$A,0)),"") | I7: =IFERROR(INDEX(BASE!$F:$F,MATCH(INICIO!$C$18&"-"&$C7,BASE!$A:$A,0)),"") | J7: =IFERROR(INDEX(BASE!$G:$G,MATCH(INICIO!$C$18&"-"&$C7,BASE!$A:$A,0)),"") | K7: 0.2 | L7: 0.35 | M7: 0.45 | N7: =K7+L7+M7 | O7: 0.3 | P7: =IF($G7="No",0,ROUND(5*K7+3*L7+1*M7,0)) | Q7: =IF($G7="No",0,ROUND(1+4*(K7+L7),0)) | R7: =P7*Q7 | S7: Es el elemento de mayor exposicion del giro: el ticket promedio del periodo supera por si solo el umbral de aviso, de modo que casi toda la operacion nace ya dentro del regimen.
B8: 1 | C8: 2 | D8: Liquidez: facilidad de convertir en dinero | F8: B | G8: Sí | H8: =IFERROR(INDEX(BASE!$E:$E,MATCH(INICIO!$C$18&"-"&$C8,BASE!$A:$A,0)),"") | I8: =IFERROR(INDEX(BASE!$F:$F,MATCH(INICIO!$C$18&"-"&$C8,BASE!$A:$A,0)),"") | J8: =IFERROR(INDEX(BASE!$G:$G,MATCH(INICIO!$C$18&"-"&$C8,BASE!$A:$A,0)),"") | K8: 0.15 | L8: 0.3 | M8: 0.55 | N8: =K8+L8+M8 | O8: 0.1 | P8: =IF($G8="No",0,ROUND(5*K8+3*L8+1*M8,0)) | Q8: =IF($G8="No",0,ROUND(1+4*(K8+L8),0)) | R8: =P8*Q8 | S8: El inmueble es el activo menos liquido del catalogo del Art. 17; la conversion exige escritura publica y registro, lo que reduce su atractivo para colocacion rapida.
B9: 1 | C9: 3 | D9: Anonimato: si el beneficiario queda a la vista | F9: B | G9: Sí | H9: =IFERROR(INDEX(BASE!$E:$E,MATCH(INICIO!$C$18&"-"&$C9,BASE!$A:$A,0)),"") | I9: =IFERROR(INDEX(BASE!$F:$F,MATCH(INICIO!$C$18&"-"&$C9,BASE!$A:$A,0)),"") | J9: =IFERROR(INDEX(BASE!$G:$G,MATCH(INICIO!$C$18&"-"&$C9,BASE!$A:$A,0)),"") | K9: 0.45 | L9: 0.3 | M9: 0.25 | N9: =K9+L9+M9 | O9: 0.25 | P9: =IF($G9="No",0,ROUND(5*K9+3*L9+1*M9,0)) | Q9: =IF($G9="No",0,ROUND(1+4*(K9+L9),0)) | R9: =P9*Q9 | S9: Peso alto: la interposicion de terceros y la compra a traves de personas morales de reciente constitucion es la tipologia inmobiliaria dominante en la ENR.
B10: 1 | C10: 4 | D10: Ocultamiento de valor en el precio | E10: 400 Bis | F10: B | G10: Sí | H10: =IFERROR(INDEX(BASE!$E:$E,MATCH(INICIO!$C$18&"-"&$C10,BASE!$A:$A,0)),"") | I10: =IFERROR(INDEX(BASE!$F:$F,MATCH(INICIO!$C$18&"-"&$C10,BASE!$A:$A,0)),"") | J10: =IFERROR(INDEX(BASE!$G:$G,MATCH(INICIO!$C$18&"-"&$C10,BASE!$A:$A,0)),"") | K10: 0.35 | L10: 0.35 | M10: 0.3 | N10: =K10+L10+M10 | O10: 0.25 | P10: =IF($G10="No",0,ROUND(5*K10+3*L10+1*M10,0)) | Q10: =IF($G10="No",0,ROUND(1+4*(K10+L10),0)) | R10: =P10*Q10 | S10: Peso alto por mandato del ultimo parrafo del Art. 10 Septies 1: es el indicador de 400 Bis del elemento, y la transferencia de valor via inmueble es el mecanismo tipico de integracion.
B11: 1 | C11: 5 | D11: Exposición a personas señaladas por terrorismo | E11: 139 Quáter | F11: B | G11: Sí | H11: =IFERROR(INDEX(BASE!$E:$E,MATCH(INICIO!$C$18&"-"&$C11,BASE!$A:$A,0)),"") | I11: =IFERROR(INDEX(BASE!$F:$F,MATCH(INICIO!$C$18&"-"&$C11,BASE!$A:$A,0)),"") | J11: =IFERROR(INDEX(BASE!$G:$G,MATCH(INICIO!$C$18&"-"&$C11,BASE!$A:$A,0)),"") | K11: 0.1 | L11: 0.2 | M11: 0.7 | N11: =K11+L11+M11 | O11: 0.1 | P11: =IF($G11="No",0,ROUND(5*K11+3*L11+1*M11,0)) | Q11: =IF($G11="No",0,ROUND(1+4*(K11+L11),0)) | R11: =P11*Q11 | S11: Se mantiene por obligacion normativa como indicador de 139 Quater del elemento, con peso bajo: no se detectaron contrapartes ni destinos vinculados a financiamiento al terrorismo en el periodo.
B12: 2 | C12: 6 | D12: Tipo de persona | F12: A | G12: Sí | H12: =IFERROR(INDEX(BASE!$E:$E,MATCH(INICIO!$C$18&"-"&$C12,BASE!$A:$A,0)),"") | I12: =IFERROR(INDEX(BASE!$F:$F,MATCH(INICIO!$C$18&"-"&$C12,BASE!$A:$A,0)),"") | J12: =IFERROR(INDEX(BASE!$G:$G,MATCH(INICIO!$C$18&"-"&$C12,BASE!$A:$A,0)),"") | K12: 0.3 | L12: 0.35 | M12: 0.35 | N12: =K12+L12+M12 | O12: 0.18 | P12: =IF($G12="No",0,ROUND(5*K12+3*L12+1*M12,0)) | Q12: =IF($G12="No",0,ROUND(1+4*(K12+L12),0)) | R12: =P12*Q12 | S12: La estructura del cliente es el primer discriminante del giro: persona moral con socios no identificables concentra la mayor parte de las alertas del periodo.
B13: 2 | C13: 7 | D13: Antigüedad del Cliente | F13: A | G13: Sí | H13: =IFERROR(INDEX(BASE!$E:$E,MATCH(INICIO!$C$18&"-"&$C13,BASE!$A:$A,0)),"") | I13: =IFERROR(INDEX(BASE!$F:$F,MATCH(INICIO!$C$18&"-"&$C13,BASE!$A:$A,0)),"") | J13: =IFERROR(INDEX(BASE!$G:$G,MATCH(INICIO!$C$18&"-"&$C13,BASE!$A:$A,0)),"") | K13: 0.15 | L13: 0.3 | M13: 0.55 | N13: =K13+L13+M13 | O13: 0.08 | P13: =IF($G13="No",0,ROUND(5*K13+3*L13+1*M13,0)) | Q13: =IF($G13="No",0,ROUND(1+4*(K13+L13),0)) | R13: =P13*Q13 | S13: Peso bajo: la antiguedad por si sola discrimina poco, pero se conserva porque la sociedad constituida en el mismo ejercicio de la compra es senal de alerta reconocida.
B14: 2 | C14: 8 | D14: Giro o actividad declarada | F14: A | G14: Sí | H14: =IFERROR(INDEX(BASE!$E:$E,MATCH(INICIO!$C$18&"-"&$C14,BASE!$A:$A,0)),"") | I14: =IFERROR(INDEX(BASE!$F:$F,MATCH(INICIO!$C$18&"-"&$C14,BASE!$A:$A,0)),"") | J14: =IFERROR(INDEX(BASE!$G:$G,MATCH(INICIO!$C$18&"-"&$C14,BASE!$A:$A,0)),"") | K14: 0.4 | L14: 0.3 | M14: 0.3 | N14: =K14+L14+M14 | O14: 0.15 | P14: =IF($G14="No",0,ROUND(5*K14+3*L14+1*M14,0)) | Q14: =IF($G14="No",0,ROUND(1+4*(K14+L14),0)) | R14: =P14*Q14 | S14: El giro del cliente explica la congruencia entre el precio del inmueble y su capacidad economica declarada; es la pregunta que abre cualquier revision.
B15: 2 | C15: 9 | D15: Nacionalidad | F15: A | G15: Sí | H15: =IFERROR(INDEX(BASE!$E:$E,MATCH(INICIO!$C$18&"-"&$C15,BASE!$A:$A,0)),"") | I15: =IFERROR(INDEX(BASE!$F:$F,MATCH(INICIO!$C$18&"-"&$C15,BASE!$A:$A,0)),"") | J15: =IFERROR(INDEX(BASE!$G:$G,MATCH(INICIO!$C$18&"-"&$C15,BASE!$A:$A,0)),"") | K15: 0.1 | L15: 0.25 | M15: 0.65 | N15: =K15+L15+M15 | O15: 0.07 | P15: =IF($G15="No",0,ROUND(5*K15+3*L15+1*M15,0)) | Q15: =IF($G15="No",0,ROUND(1+4*(K15+L15),0)) | R15: =P15*Q15 | S15: Peso bajo: la nacionalidad aisladamente no explica riesgo. Su efecto real se mide en el indicador de residencia y en el elemento 3.
B16: 2 | C16: 10 | D16: País y entidad de residencia | F16: A | G16: Sí | H16: =IFERROR(INDEX(BASE!$E:$E,MATCH(INICIO!$C$18&"-"&$C16,BASE!$A:$A,0)),"") | I16: =IFERROR(INDEX(BASE!$F:$F,MATCH(INICIO!$C$18&"-"&$C16,BASE!$A:$A,0)),"") | J16: =IFERROR(INDEX(BASE!$G:$G,MATCH(INICIO!$C$18&"-"&$C16,BASE!$A:$A,0)),"") | K16: 0.15 | L16: 0.25 | M16: 0.6 | N16: =K16+L16+M16 | O16: 0.1 | P16: =IF($G16="No",0,ROUND(5*K16+3*L16+1*M16,0)) | Q16: =IF($G16="No",0,ROUND(1+4*(K16+L16),0)) | R16: =P16*Q16 | S16: Peso medio bajo: la residencia fuera de la plaza donde esta el inmueble es senal util, pero se pondera junto con el indicador 17 para no contar dos veces lo mismo.
B17: 2 | C17: 11 | D17: Condición de Persona Políticamente Expuesta | E17: 400 Bis | F17: D | G17: Sí | H17: =IFERROR(INDEX(BASE!$E:$E,MATCH(INICIO!$C$18&"-"&$C17,BASE!$A:$A,0)),"") | I17: =IFERROR(INDEX(BASE!$F:$F,MATCH(INICIO!$C$18&"-"&$C17,BASE!$A:$A,0)),"") | J17: =IFERROR(INDEX(BASE!$G:$G,MATCH(INICIO!$C$18&"-"&$C17,BASE!$A:$A,0)),"") | K17: 0.2 | L17: 0.2 | M17: 0.6 | N17: =K17+L17+M17 | O17: 0.14 | P17: =IF($G17="No",0,ROUND(5*K17+3*L17+1*M17,0)) | Q17: =IF($G17="No",0,ROUND(1+4*(K17+L17),0)) | R17: =P17*Q17 | S17: Indicador de 400 Bis del elemento. Peso relevante: la condicion PEP dispara seguimiento reforzado por el Art. 23 Bis 3, y la PEP extranjera fuerza grado alto por el Art. 23 Bis 4.
B18: 2 | C18: 12 | D18: Resultado de la búsqueda en listas | E18: 139 Quáter | F18: D | G18: Sí | H18: =IFERROR(INDEX(BASE!$E:$E,MATCH(INICIO!$C$18&"-"&$C18,BASE!$A:$A,0)),"") | I18: =IFERROR(INDEX(BASE!$F:$F,MATCH(INICIO!$C$18&"-"&$C18,BASE!$A:$A,0)),"") | J18: =IFERROR(INDEX(BASE!$G:$G,MATCH(INICIO!$C$18&"-"&$C18,BASE!$A:$A,0)),"") | K18: 0.05 | L18: 0.15 | M18: 0.8 | N18: =K18+L18+M18 | O18: 0.1 | P18: =IF($G18="No",0,ROUND(5*K18+3*L18+1*M18,0)) | Q18: =IF($G18="No",0,ROUND(1+4*(K18+L18),0)) | R18: =P18*Q18 | S18: Indicador de 139 Quater del elemento. Peso contenido porque la validacion contra listas esta automatizada y se ejecuta al 100% de las operaciones.
B19: 2 | C19: 13 | D19: Profundidad de la cadena de control | E19: 400 Bis | F19: A | G19: Sí | H19: =IFERROR(INDEX(BASE!$E:$E,MATCH(INICIO!$C$18&"-"&$C19,BASE!$A:$A,0)),"") | I19: =IFERROR(INDEX(BASE!$F:$F,MATCH(INICIO!$C$18&"-"&$C19,BASE!$A:$A,0)),"") | J19: =IFERROR(INDEX(BASE!$G:$G,MATCH(INICIO!$C$18&"-"&$C19,BASE!$A:$A,0)),"") | K19: 0.35 | L19: 0.35 | M19: 0.3 | N19: =K19+L19+M19 | O19: 0.18 | P19: =IF($G19="No",0,ROUND(5*K19+3*L19+1*M19,0)) | Q19: =IF($G19="No",0,ROUND(1+4*(K19+L19),0)) | R19: =P19*Q19 | S19: Peso alto: desde el 30 de noviembre de 2026 desaparece la constancia declarativa en persona moral y fideicomiso, y hay que identificar al Beneficiario Controlador. La complejidad de la cadena es riesgo medible.
B20: 3 | C20: 14 | D20: País donde se realiza la operación | E20: 400 Bis | F20: C+D | G20: Sí | H20: =IFERROR(INDEX(BASE!$E:$E,MATCH(INICIO!$C$18&"-"&$C20,BASE!$A:$A,0)),"") | I20: =IFERROR(INDEX(BASE!$F:$F,MATCH(INICIO!$C$18&"-"&$C20,BASE!$A:$A,0)),"") | J20: =IFERROR(INDEX(BASE!$G:$G,MATCH(INICIO!$C$18&"-"&$C20,BASE!$A:$A,0)),"") | K20: 0.15 | L20: 0.25 | M20: 0.6 | N20: =K20+L20+M20 | O20: 0.3 | P20: =IF($G20="No",0,ROUND(5*K20+3*L20+1*M20,0)) | Q20: =IF($G20="No",0,ROUND(1+4*(K20+L20),0)) | R20: =P20*Q20 | S20: Indicador de 400 Bis del elemento y el de mayor peso: la jurisdiccion donde se ubica el inmueble determina el marco registral y la trazabilidad real de la operacion.
B21: 3 | C21: 15 | D21: Entidad o municipio de la operación | F21: C+D | G21: Sí | H21: =IFERROR(INDEX(BASE!$E:$E,MATCH(INICIO!$C$18&"-"&$C21,BASE!$A:$A,0)),"") | I21: =IFERROR(INDEX(BASE!$F:$F,MATCH(INICIO!$C$18&"-"&$C21,BASE!$A:$A,0)),"") | J21: =IFERROR(INDEX(BASE!$G:$G,MATCH(INICIO!$C$18&"-"&$C21,BASE!$A:$A,0)),"") | K21: 0.3 | L21: 0.35 | M21: 0.35 | N21: =K21+L21+M21 | O21: 0.3 | P21: =IF($G21="No",0,ROUND(5*K21+3*L21+1*M21,0)) | Q21: =IF($G21="No",0,ROUND(1+4*(K21+L21),0)) | R21: =P21*Q21 | S21: Peso equivalente al anterior: la plaza nacional concentra la exposicion. Dos de los desarrollos del periodo estan en municipios senalados en la ENR.
B22: 3 | C22: 16 | D22: Vínculo con jurisdicción sancionada o de acción requerida | E22: 139 Quáter | F22: C+D | G22: Sí | H22: =IFERROR(INDEX(BASE!$E:$E,MATCH(INICIO!$C$18&"-"&$C22,BASE!$A:$A,0)),"") | I22: =IFERROR(INDEX(BASE!$F:$F,MATCH(INICIO!$C$18&"-"&$C22,BASE!$A:$A,0)),"") | J22: =IFERROR(INDEX(BASE!$G:$G,MATCH(INICIO!$C$18&"-"&$C22,BASE!$A:$A,0)),"") | K22: 0.05 | L22: 0.15 | M22: 0.8 | N22: =K22+L22+M22 | O22: 0.15 | P22: =IF($G22="No",0,ROUND(5*K22+3*L22+1*M22,0)) | Q22: =IF($G22="No",0,ROUND(1+4*(K22+L22),0)) | R22: =P22*Q22 | S22: Indicador de 139 Quater del elemento, con peso bajo: la operacion del periodo fue integramente nacional, sin contrapartes en jurisdicciones sancionadas.
B23: 3 | C23: 17 | D23: Coincidencia entre domicilio y lugar de la operación | E23: 400 Bis | F23: A+C | G23: Sí | H23: =IFERROR(INDEX(BASE!$E:$E,MATCH(INICIO!$C$18&"-"&$C23,BASE!$A:$A,0)),"") | I23: =IFERROR(INDEX(BASE!$F:$F,MATCH(INICIO!$C$18&"-"&$C23,BASE!$A:$A,0)),"") | J23: =IFERROR(INDEX(BASE!$G:$G,MATCH(INICIO!$C$18&"-"&$C23,BASE!$A:$A,0)),"") | K23: 0.25 | L23: 0.3 | M23: 0.45 | N23: =K23+L23+M23 | O23: 0.25 | P23: =IF($G23="No",0,ROUND(5*K23+3*L23+1*M23,0)) | Q23: =IF($G23="No",0,ROUND(1+4*(K23+L23),0)) | R23: =P23*Q23 | S23: Peso alto: la incongruencia entre el domicilio del cliente y la ubicacion del inmueble es la alerta que mas veces se activo en el periodo evaluado.
B24: 4 | C24: 18 | D24: Instrumento con que se paga | F24: C | G24: Sí | H24: =IFERROR(INDEX(BASE!$E:$E,MATCH(INICIO!$C$18&"-"&$C24,BASE!$A:$A,0)),"") | I24: =IFERROR(INDEX(BASE!$F:$F,MATCH(INICIO!$C$18&"-"&$C24,BASE!$A:$A,0)),"") | J24: =IFERROR(INDEX(BASE!$G:$G,MATCH(INICIO!$C$18&"-"&$C24,BASE!$A:$A,0)),"") | K24: 0.5 | L24: 0.25 | M24: 0.25 | N24: =K24+L24+M24 | O24: 0.22 | P24: =IF($G24="No",0,ROUND(5*K24+3*L24+1*M24,0)) | Q24: =IF($G24="No",0,ROUND(1+4*(K24+L24),0)) | R24: =P24*Q24 | S24: El peso mas alto del elemento: el efectivo es el mecanismo de colocacion por excelencia y la mitad de las operaciones del periodo tuvo algun componente en efectivo.
B25: 4 | C25: 19 | D25: Moneda de la operación | F25: C | G25: Sí | H25: =IFERROR(INDEX(BASE!$E:$E,MATCH(INICIO!$C$18&"-"&$C25,BASE!$A:$A,0)),"") | I25: =IFERROR(INDEX(BASE!$F:$F,MATCH(INICIO!$C$18&"-"&$C25,BASE!$A:$A,0)),"") | J25: =IFERROR(INDEX(BASE!$G:$G,MATCH(INICIO!$C$18&"-"&$C25,BASE!$A:$A,0)),"") | K25: 0.1 | L25: 0.2 | M25: 0.7 | N25: =K25+L25+M25 | O25: 0.05 | P25: =IF($G25="No",0,ROUND(5*K25+3*L25+1*M25,0)) | Q25: =IF($G25="No",0,ROUND(1+4*(K25+L25),0)) | R25: =P25*Q25 | S25: Peso minimo: el 100% de las operaciones del periodo se pacto y liquido en pesos mexicanos.
B26: 4 | C26: 20 | D26: Monto frente al umbral de tu fracción | F26: C | G26: Sí | H26: =IFERROR(INDEX(BASE!$E:$E,MATCH(INICIO!$C$18&"-"&$C26,BASE!$A:$A,0)),"") | I26: =IFERROR(INDEX(BASE!$F:$F,MATCH(INICIO!$C$18&"-"&$C26,BASE!$A:$A,0)),"") | J26: =IFERROR(INDEX(BASE!$G:$G,MATCH(INICIO!$C$18&"-"&$C26,BASE!$A:$A,0)),"") | K26: 0.35 | L26: 0.3 | M26: 0.35 | N26: =K26+L26+M26 | O26: 0.13 | P26: =IF($G26="No",0,ROUND(5*K26+3*L26+1*M26,0)) | Q26: =IF($G26="No",0,ROUND(1+4*(K26+L26),0)) | R26: =P26*Q26 | S26: Peso medio: el monto frente al umbral define si la operacion entra al regimen, pero en este giro practicamente todas lo superan, de modo que discrimina poco entre clientes.
B27: 4 | C27: 21 | D27: Número y ritmo de operaciones en el periodo | F27: C | G27: Sí | H27: =IFERROR(INDEX(BASE!$E:$E,MATCH(INICIO!$C$18&"-"&$C27,BASE!$A:$A,0)),"") | I27: =IFERROR(INDEX(BASE!$F:$F,MATCH(INICIO!$C$18&"-"&$C27,BASE!$A:$A,0)),"") | J27: =IFERROR(INDEX(BASE!$G:$G,MATCH(INICIO!$C$18&"-"&$C27,BASE!$A:$A,0)),"") | K27: 0.3 | L27: 0.35 | M27: 0.35 | N27: =K27+L27+M27 | O27: 0.15 | P27: =IF($G27="No",0,ROUND(5*K27+3*L27+1*M27,0)) | Q27: =IF($G27="No",0,ROUND(1+4*(K27+L27),0)) | R27: =P27*Q27 | S27: Peso relevante: el pago en parcialidades es la practica normal del giro, lo que hace dificil distinguir la amortizacion legitima del fraccionamiento deliberado.
B28: 4 | C28: 22 | D28: Canal: certeza de identificación del Cliente | E28: 400 Bis | F28: B+C | G28: Sí | H28: =IFERROR(INDEX(BASE!$E:$E,MATCH(INICIO!$C$18&"-"&$C28,BASE!$A:$A,0)),"") | I28: =IFERROR(INDEX(BASE!$F:$F,MATCH(INICIO!$C$18&"-"&$C28,BASE!$A:$A,0)),"") | J28: =IFERROR(INDEX(BASE!$G:$G,MATCH(INICIO!$C$18&"-"&$C28,BASE!$A:$A,0)),"") | K28: 0.25 | L28: 0.35 | M28: 0.4 | N28: =K28+L28+M28 | O28: 0.1 | P28: =IF($G28="No",0,ROUND(5*K28+3*L28+1*M28,0)) | Q28: =IF($G28="No",0,ROUND(1+4*(K28+L28),0)) | R28: =P28*Q28 | S28: Indicador de 400 Bis del elemento. Peso contenido: la operacion es presencial y ante fedatario, lo que limita el riesgo de canal.
B29: 4 | C29: 23 | D29: Acreditación del origen de los recursos | F29: C+D | G29: Sí | H29: =IFERROR(INDEX(BASE!$E:$E,MATCH(INICIO!$C$18&"-"&$C29,BASE!$A:$A,0)),"") | I29: =IFERROR(INDEX(BASE!$F:$F,MATCH(INICIO!$C$18&"-"&$C29,BASE!$A:$A,0)),"") | J29: =IFERROR(INDEX(BASE!$G:$G,MATCH(INICIO!$C$18&"-"&$C29,BASE!$A:$A,0)),"") | K29: 0.45 | L29: 0.3 | M29: 0.25 | N29: =K29+L29+M29 | O29: 0.18 | P29: =IF($G29="No",0,ROUND(5*K29+3*L29+1*M29,0)) | Q29: =IF($G29="No",0,ROUND(1+4*(K29+L29),0)) | R29: =P29*Q29 | S29: Peso alto: el origen de los recursos es el dato que sostiene o derrumba toda la operacion, y es la primera pregunta de cualquier requerimiento.
B30: 4 | C30: 24 | D30: Acreditación del destino de los recursos o del bien | F30: C+D | G30: Sí | H30: =IFERROR(INDEX(BASE!$E:$E,MATCH(INICIO!$C$18&"-"&$C30,BASE!$A:$A,0)),"") | I30: =IFERROR(INDEX(BASE!$F:$F,MATCH(INICIO!$C$18&"-"&$C30,BASE!$A:$A,0)),"") | J30: =IFERROR(INDEX(BASE!$G:$G,MATCH(INICIO!$C$18&"-"&$C30,BASE!$A:$A,0)),"") | K30: 0.3 | L30: 0.3 | M30: 0.4 | N30: =K30+L30+M30 | O30: 0.09 | P30: =IF($G30="No",0,ROUND(5*K30+3*L30+1*M30,0)) | Q30: =IF($G30="No",0,ROUND(1+4*(K30+L30),0)) | R30: =P30*Q30 | S30: Peso menor que el origen: en compraventa de inmueble el destino es el propio bien, que queda registrado; el riesgo se concentra en la entrada de los recursos.
B31: 4 | C31: 25 | D31: Combinación de canal e instrumento idónea para el financiamiento al terrorismo | E31: 139 Quáter | F31: B+C | G31: Sí | H31: =IFERROR(INDEX(BASE!$E:$E,MATCH(INICIO!$C$18&"-"&$C31,BASE!$A:$A,0)),"") | I31: =IFERROR(INDEX(BASE!$F:$F,MATCH(INICIO!$C$18&"-"&$C31,BASE!$A:$A,0)),"") | J31: =IFERROR(INDEX(BASE!$G:$G,MATCH(INICIO!$C$18&"-"&$C31,BASE!$A:$A,0)),"") | K31: 0.2 | L31: 0.3 | M31: 0.5 | N31: =K31+L31+M31 | O31: 0.08 | P31: =IF($G31="No",0,ROUND(5*K31+3*L31+1*M31,0)) | Q31: =IF($G31="No",0,ROUND(1+4*(K31+L31),0)) | R31: =P31*Q31 | S31: Indicador de 139 Quater del elemento. Peso bajo: no se identificaron canales ni instrumentos de los descritos en la ENR para financiamiento al terrorismo.
B33: RESUMEN POR ELEMENTO
B34: Elemento | D34: Peso | E34: Calif. | F34: Conc. | G34: Riesgo | H34: Nivel | I34: N/A | J34: Aviso | K34: Justificación del peso asignado (Art. 10 Septies 1, fr. II)
B35: 1. Actos u operaciones | D35: 0.2 | E35: =IFERROR(SUMPRODUCT($P$7:$P$11,$O$7:$O$11,--($G$7:$G$11="Sí"))/SUMPRODUCT($O$7:$O$11,--($G$7:$G$11="Sí")),0) | F35: =IFERROR(SUMPRODUCT($Q$7:$Q$11,$O$7:$O$11,--($G$7:$G$11="Sí"))/SUMPRODUCT($O$7:$O$11,--($G$7:$G$11="Sí")),0) | G35: =E35*F35 | H35: =IFERROR(INDEX(PARAMETROS!$E$15:$E$19,MATCH(G35,PARAMETROS!$B$15:$B$19,1)),"") | I35: =COUNTIF($G$7:$G$11,"No") | J35: =IF(I35>5/3,"Revisar: más de un tercio del elemento está en No aplica","") | K35: La entidad realiza un solo tipo de acto —compraventa de inmueble destinado a casa habitación y local comercial— de alto valor unitario y baja liquidez. Se le asigna 20% porque el acto en sí está bien acotado y registrado ante fedatario: la exposición no está en qué se vende, sino en con quién y cómo se paga.
B36: 2. Clientes / Usuarios | D36: 0.3 | E36: =IFERROR(SUMPRODUCT($P$12:$P$19,$O$12:$O$19,--($G$12:$G$19="Sí"))/SUMPRODUCT($O$12:$O$19,--($G$12:$G$19="Sí")),0) | F36: =IFERROR(SUMPRODUCT($Q$12:$Q$19,$O$12:$O$19,--($G$12:$G$19="Sí"))/SUMPRODUCT($O$12:$O$19,--($G$12:$G$19="Sí")),0) | G36: =E36*F36 | H36: =IFERROR(INDEX(PARAMETROS!$E$15:$E$19,MATCH(G36,PARAMETROS!$B$15:$B$19,1)),"") | I36: =COUNTIF($G$12:$G$19,"No") | J36: =IF(I36>8/3,"Revisar: más de un tercio del elemento está en No aplica","") | K36: Es donde se concentra la exposición real. De los 86 Clientes del periodo, 31 son personas morales y 9 de ellas se constituyeron en los doce meses previos a la operación. La interposición de terceros y la opacidad de la cadena de propiedad son la tipología inmobiliaria dominante en la Evaluación Nacional de Riesgos. Se le asigna 30%.
B37: 3. Países y áreas geográficas | D37: 0.15 | E37: =IFERROR(SUMPRODUCT($P$20:$P$23,$O$20:$O$23,--($G$20:$G$23="Sí"))/SUMPRODUCT($O$20:$O$23,--($G$20:$G$23="Sí")),0) | F37: =IFERROR(SUMPRODUCT($Q$20:$Q$23,$O$20:$O$23,--($G$20:$G$23="Sí"))/SUMPRODUCT($O$20:$O$23,--($G$20:$G$23="Sí")),0) | G37: =E37*F37 | H37: =IFERROR(INDEX(PARAMETROS!$E$15:$E$19,MATCH(G37,PARAMETROS!$B$15:$B$19,1)),"") | I37: =COUNTIF($G$20:$G$23,"No") | J37: =IF(I37>4/3,"Revisar: más de un tercio del elemento está en No aplica","") | K37: La operación es local: los cuatro desarrollos están en el área metropolitana y no hubo contrapartes ni recursos de jurisdicciones extranjeras en el periodo. Se le asigna 15%, el peso más bajo, y no cero: dos de los desarrollos están en municipios señalados en la ENR, y eso se mide en el indicador 15.
B38: 4. Transacciones y canales | D38: 0.35 | E38: =IFERROR(SUMPRODUCT($P$24:$P$31,$O$24:$O$31,--($G$24:$G$31="Sí"))/SUMPRODUCT($O$24:$O$31,--($G$24:$G$31="Sí")),0) | F38: =IFERROR(SUMPRODUCT($Q$24:$Q$31,$O$24:$O$31,--($G$24:$G$31="Sí"))/SUMPRODUCT($O$24:$O$31,--($G$24:$G$31="Sí")),0) | G38: =E38*F38 | H38: =IFERROR(INDEX(PARAMETROS!$E$15:$E$19,MATCH(G38,PARAMETROS!$B$15:$B$19,1)),"") | I38: =COUNTIF($G$24:$G$31,"No") | J38: =IF(I38>8/3,"Revisar: más de un tercio del elemento está en No aplica","") | K38: El mayor peso, 35%. Es donde se materializa el riesgo: 56 de las 112 operaciones tuvieron algún componente en efectivo, 41 se liquidaron en parcialidades y en 7 casos el pago provino de un tercero distinto del comprador. Los tres hechos están documentados en el reporte de acumulación del sistema.
B40: RIESGO DE LA ENTIDAD | D40: =SUM(D35:D38) | E40: =IFERROR(SUMPRODUCT(E35:E38,D35:D38)/SUM(D35:D38),0) | F40: =IFERROR(SUMPRODUCT(F35:F38,D35:D38)/SUM(D35:D38),0) | G40: =E40*F40 | H40: =IFERROR(INDEX(PARAMETROS!$E$15:$E$19,MATCH(G40,PARAMETROS!$B$15:$B$19,1)),"") | I40: =COUNTIF($G$7:$G$31,"No") | J40: =IF(SUMPRODUCT(--($G$7:$G$31="No"),--($S$7:$S$31=""))>0,"Hay exclusiones sin justificación escrita: no son defendibles ante un requerimiento","") | K40: =IF(ABS(SUM($D$35:$D$38)-1)>0.001,"Los pesos de los cuatro elementos suman "&TEXT(SUM($D$35:$D$38),"0%")&" y deben sumar 100%. Corrige la columna Peso.","Los pesos de los elementos suman 100%.")
K41: El peso de cada indicador (columna Peso) es relativo dentro de su elemento: el promedio se normaliza solo. El peso de los cuatro elementos sí debe sumar 100%.
B42: Trazabilidad (Art. 10 Septies 1, fr. I y último párrafo): indicadores evaluados y excluidos
B43: Indicadores evaluados: | E43: =COUNTIF($G$7:$G$31,"Sí")
...

Sheet A2 CONSECUENCIAS
B2: A2 · CONSECUENCIAS SI EL RIESGO SE MATERIALIZA (análisis cualitativo)
B3: Esta hoja NO alimenta el cálculo y no cambia ningún número. En una sola descripción, explica qué pasaría si el riesgo LD/FT se materializa en tu entidad. Sirve para justificar el nivel de tolerancia declarado y para sustentar la evaluación ante un requerimiento.
B4: Paso 4 de 10 · Viene de: A1 · Sigue: A3 INHERENTE (solo lectura)
B6: ¿Qué pasaría si el riesgo LD/FT se materializa en tu entidad? | G6: Severidad (ref.)
B7: Si una operación con recursos de procedencia ilícita se materializara en la entidad, el impacto sería simultáneo en cuatro planos. LEGAL: la multa por Aviso omitido es de 10,000 a 65,000 UMA, o del 10 al 100 % del valor del acto cuando sea cuantificable, la que resulte mayor (Art. 53 fr. VI con Art. 54 fr. III de la Ley) —entre $1,173,100 y $7,625,150 al valor vigente de la UMA, y en una operación de este tamaño manda el porcentaje— y la conducta puede escalar a responsabilidad penal por el Art. 400 Bis del Código Penal Federal para quien intervino a sabiendas. REPUTACIONAL: el negocio depende de la recomendación entre compradores y de la relación con tres desarrolladoras; una nota pública o un requerimiento conocido bastaría para frenar la preventa del desarrollo en curso. DE CONTAGIO: las instituciones financieras con las que se dispersan los recursos aplican sus propias medidas del Art. 115 de la LIC y pueden restringir o cancelar las cuentas de la entidad, lo que detendría la operación aunque no hubiera sanción. OPERATIVO: atender un requerimiento con expedientes incompletos consumiría a la Encargada de Cumplimiento y al área jurídica durante semanas, con el costo de oportunidad correspondiente. | G7: Grave
B9: Guía: cubre en la misma redacción las cuatro caras del impacto — legal (multas y sanciones), reputacional (imagen y pérdida de clientes), de contagio (relación con terceros ilícitos) y operativa (interrupción y costos). No hace falta separarlas por elemento de riesgo.

Sheet A3 INHERENTE
B2: A3 · RIESGO INHERENTE = Calificación × Concentración (antes de controles)
B3: Resultado en tres niveles: por elemento, por indicador y de la entidad.
B4: Paso 5 de 10 · Se calcula solo · Sigue: A4 CONTROLES MINIMOS
B5: RIESGO INHERENTE POR ELEMENTO
B6: Elemento | C6: Calif. | D6: Conc. | E6: Riesgo | F6: Nivel
B7: 1. Actos u operaciones | C7: ='A1 EXPOSICION'!E35 | D7: ='A1 EXPOSICION'!F35 | E7: ='A1 EXPOSICION'!G35 | F7: =IFERROR(INDEX(PARAMETROS!$E$15:$E$19,MATCH(E7,PARAMETROS!$B$15:$B$19,1)),"")
B8: 2. Clientes / Usuarios | C8: ='A1 EXPOSICION'!E36 | D8: ='A1 EXPOSICION'!F36 | E8: ='A1 EXPOSICION'!G36 | F8: =IFERROR(INDEX(PARAMETROS!$E$15:$E$19,MATCH(E8,PARAMETROS!$B$15:$B$19,1)),"")
B9: 3. Países y áreas geográficas | C9: ='A1 EXPOSICION'!E37 | D9: ='A1 EXPOSICION'!F37 | E9: ='A1 EXPOSICION'!G37 | F9: =IFERROR(INDEX(PARAMETROS!$E$15:$E$19,MATCH(E9,PARAMETROS!$B$15:$B$19,1)),"")
B10: 4. Transacciones y canales | C10: ='A1 EXPOSICION'!E38 | D10: ='A1 EXPOSICION'!F38 | E10: ='A1 EXPOSICION'!G38 | F10: =IFERROR(INDEX(PARAMETROS!$E$15:$E$19,MATCH(E10,PARAMETROS!$B$15:$B$19,1)),"")
B12: RIESGO INHERENTE DE LA ENTIDAD | C12: ='A1 EXPOSICION'!E40 | D12: ='A1 EXPOSICION'!F40 | E12: ='A1 EXPOSICION'!G40 | F12: =IFERROR(INDEX(PARAMETROS!$E$15:$E$19,MATCH(E12,PARAMETROS!$B$15:$B$19,1)),"")
B14: RIESGO INHERENTE POR INDICADOR
B15: # | C15: Indicador | D15: Calif. | E15: Conc. | F15: Riesgo | G15: Nivel
B16: 1 | C16: ='A1 EXPOSICION'!D7 | D16: =IF('A1 EXPOSICION'!$G7="No","N/A",'A1 EXPOSICION'!P7) | E16: =IF('A1 EXPOSICION'!$G7="No","N/A",'A1 EXPOSICION'!Q7) | F16: =IF('A1 EXPOSICION'!$G7="No","N/A",'A1 EXPOSICION'!R7) | G16: =IF('A1 EXPOSICION'!$G7="No","No aplica",IFERROR(INDEX(PARAMETROS!$E$15:$E$19,MATCH(F16,PARAMETROS!$B$15:$B$19,1)),""))
B17: 2 | C17: ='A1 EXPOSICION'!D8 | D17: =IF('A1 EXPOSICION'!$G8="No","N/A",'A1 EXPOSICION'!P8) | E17: =IF('A1 EXPOSICION'!$G8="No","N/A",'A1 EXPOSICION'!Q8) | F17: =IF('A1 EXPOSICION'!$G8="No","N/A",'A1 EXPOSICION'!R8) | G17: =IF('A1 EXPOSICION'!$G8="No","No aplica",IFERROR(INDEX(PARAMETROS!$E$15:$E$19,MATCH(F17,PARAMETROS!$B$15:$B$19,1)),""))
B18: 3 | C18: ='A1 EXPOSICION'!D9 | D18: =IF('A1 EXPOSICION'!$G9="No","N/A",'A1 EXPOSICION'!P9) | E18: =IF('A1 EXPOSICION'!$G9="No","N/A",'A1 EXPOSICION'!Q9) | F18: =IF('A1 EXPOSICION'!$G9="No","N/A",'A1 EXPOSICION'!R9) | G18: =IF('A1 EXPOSICION'!$G9="No","No aplica",IFERROR(INDEX(PARAMETROS!$E$15:$E$19,MATCH(F18,PARAMETROS!$B$15:$B$19,1)),""))
B19: 4 | C19: ='A1 EXPOSICION'!D10 | D19: =IF('A1 EXPOSICION'!$G10="No","N/A",'A1 EXPOSICION'!P10) | E19: =IF('A1 EXPOSICION'!$G10="No","N/A",'A1 EXPOSICION'!Q10) | F19: =IF('A1 EXPOSICION'!$G10="No","N/A",'A1 EXPOSICION'!R10) | G19: =IF('A1 EXPOSICION'!$G10="No","No aplica",IFERROR(INDEX(PARAMETROS!$E$15:$E$19,MATCH(F19,PARAMETROS!$B$15:$B$19,1)),""))
B20: 5 | C20: ='A1 EXPOSICION'!D11 | D20: =IF('A1 EXPOSICION'!$G11="No","N/A",'A1 EXPOSICION'!P11) | E20: =IF('A1 EXPOSICION'!$G11="No","N/A",'A1 EXPOSICION'!Q11) | F20: =IF('A1 EXPOSICION'!$G11="No","N/A",'A1 EXPOSICION'!R11) | G20: =IF('A1 EXPOSICION'!$G11="No","No aplica",IFERROR(INDEX(PARAMETROS!$E$15:$E$19,MATCH(F20,PARAMETROS!$B$15:$B$19,1)),""))
B21: 6 | C21: ='A1 EXPOSICION'!D12 | D21: =IF('A1 EXPOSICION'!$G12="No","N/A",'A1 EXPOSICION'!P12) | E21: =IF('A1 EXPOSICION'!$G12="No","N/A",'A1 EXPOSICION'!Q12) | F21: =IF('A1 EXPOSICION'!$G12="No","N/A",'A1 EXPOSICION'!R12) | G21: =IF('A1 EXPOSICION'!$G12="No","No aplica",IFERROR(INDEX(PARAMETROS!$E$15:$E$19,MATCH(F21,PARAMETROS!$B$15:$B$19,1)),""))
B22: 7 | C22: ='A1 EXPOSICION'!D13 | D22: =IF('A1 EXPOSICION'!$G13="No","N/A",'A1 EXPOSICION'!P13) | E22: =IF('A1 EXPOSICION'!$G13="No","N/A",'A1 EXPOSICION'!Q13) | F22: =IF('A1 EXPOSICION'!$G13="No","N/A",'A1 EXPOSICION'!R13) | G22: =IF('A1 EXPOSICION'!$G13="No","No aplica",IFERROR(INDEX(PARAMETROS!$E$15:$E$19,MATCH(F22,PARAMETROS!$B$15:$B$19,1)),""))
B23: 8 | C23: ='A1 EXPOSICION'!D14 | D23: =IF('A1 EXPOSICION'!$G14="No","N/A",'A1 EXPOSICION'!P14) | E23: =IF('A1 EXPOSICION'!$G14="No","N/A",'A1 EXPOSICION'!Q14) | F23: =IF('A1 EXPOSICION'!$G14="No","N/A",'A1 EXPOSICION'!R14) | G23: =IF('A1 EXPOSICION'!$G14="No","No aplica",IFERROR(INDEX(PARAMETROS!$E$15:$E$19,MATCH(F23,PARAMETROS!$B$15:$B$19,1)),""))
B24: 9 | C24: ='A1 EXPOSICION'!D15 | D24: =IF('A1 EXPOSICION'!$G15="No","N/A",'A1 EXPOSICION'!P15) | E24: =IF('A1 EXPOSICION'!$G15="No","N/A",'A1 EXPOSICION'!Q15) | F24: =IF('A1 EXPOSICION'!$G15="No","N/A",'A1 EXPOSICION'!R15) | G24: =IF('A1 EXPOSICION'!$G15="No","No aplica",IFERROR(INDEX(PARAMETROS!$E$15:$E$19,MATCH(F24,PARAMETROS!$B$15:$B$19,1)),""))
B25: 10 | C25: ='A1 EXPOSICION'!D16 | D25: =IF('A1 EXPOSICION'!$G16="No","N/A",'A1 EXPOSICION'!P16) | E25: =IF('A1 EXPOSICION'!$G16="No","N/A",'A1 EXPOSICION'!Q16) | F25: =IF('A1 EXPOSICION'!$G16="No","N/A",'A1 EXPOSICION'!R16) | G25: =IF('A1 EXPOSICION'!$G16="No","No aplica",IFERROR(INDEX(PARAMETROS!$E$15:$E$19,MATCH(F25,PARAMETROS!$B$15:$B$19,1)),""))
B26: 11 | C26: ='A1 EXPOSICION'!D17 | D26: =IF('A1 EXPOSICION'!$G17="No","N/A",'A1 EXPOSICION'!P17) | E26: =IF('A1 EXPOSICION'!$G17="No","N/A",'A1 EXPOSICION'!Q17) | F26: =IF('A1 EXPOSICION'!$G17="No","N/A",'A1 EXPOSICION'!R17) | G26: =IF('A1 EXPOSICION'!$G17="No","No aplica",IFERROR(INDEX(PARAMETROS!$E$15:$E$19,MATCH(F26,PARAMETROS!$B$15:$B$19,1)),""))
B27: 12 | C27: ='A1 EXPOSICION'!D18 | D27: =IF('A1 EXPOSICION'!$G18="No","N/A",'A1 EXPOSICION'!P18) | E27: =IF('A1 EXPOSICION'!$G18="No","N/A",'A1 EXPOSICION'!Q18) | F27: =IF('A1 EXPOSICION'!$G18="No","N/A",'A1 EXPOSICION'!R18) | G27: =IF('A1 EXPOSICION'!$G18="No","No aplica",IFERROR(INDEX(PARAMETROS!$E$15:$E$19,MATCH(F27,PARAMETROS!$B$15:$B$19,1)),""))
... B40: 25 | C40: ='A1 EXPOSICION'!D31 | D40: =IF('A1 EXPOSICION'!$G31="No","N/A",'A1 EXPOSICION'!P31) | E40: =IF('A1 EXPOSICION'!$G31="No","N/A",'A1 EXPOSICION'!Q31) | F40: =IF('A1 EXPOSICION'!$G31="No","N/A",'A1 EXPOSICION'!R31) | G40: =IF('A1 EXPOSICION'!$G31="No","No aplica",IFERROR(INDEX(PARAMETROS!$E$15:$E$19,MATCH(F40,PARAMETROS!$B$15:$B$19,1)),""))
B41: Un indicador marcado «No aplica» en A1 se muestra aquí como «No aplica», no como riesgo cero: no se evaluó, no es que haya salido bajo. Sale del numerador y del denominador del elemento.
B43: MAPA DE CALOR — Calificación (col) × Concentración (fila)
B44: Conc\Calif | C44: 1 | D44: 2 | E44: 3 | F44: 4 | G44: 5
B45: 5 | C45: 5 | D45: 10 | E45: 15 | F45: 20 | G45: 25
B46: 4 | C46: 4 | D46: 8 | E46: 12 | F46: 16 | G46: 20
B47: 3 | C47: 3 | D47: 6 | E47: 9 | F47: 12 | G47: 15
B48: 2 | C48: 2 | D48: 4 | E48: 6 | F48: 8 | G48: 10
B49: 1 | C49: 1 | D49: 2 | E49: 3 | F49: 4 | G49: 5
B51: Tu entidad (nivel inherente): | D51: ='A3 INHERENTE'!$F$12

Sheet A4 CONTROLES MINIMOS
B2: A4 · CATÁLOGO DE CONTROLES MÍNIMOS — las 14 obligaciones del Manual (Art. 37 Bis)
B3: Éste es el denominador de la mitigación. La efectividad NO se promedia sobre los controles que registres: se mide contra las 14 obligaciones del catálogo. Una obligación no registrada computa 0%; solo sale del cálculo si es «No aplica» conforme al Art. 37 Bis 2 y así consta en tu Manual.
B4: Paso 6 de 10 · Viene de: A3 INHERENTE · Sigue: A5 RESIDUAL · Controles por encima del mínimo: A4 BIS
B6: Fr. | C6: Contenido mínimo del Manual (Art. 37 Bis) | D6: Fundamento verificado | E6: Qué se espera (referencia) | F6: ¿Admite «No aplica»? | G6: Resultado (Art. 48) | H6: % | I6: Numeral del Manual que lo prevé | J6: Evidencia de aplicación efectiva y dónde se resguarda | K6: Justificación del «No aplica» (numeral del Manual, Art. 37 Bis 2) | L6: Aviso
B7: I | C7: Criterios para la identificación y conocimiento de Clientes o Usuarias | D7: Arts. 12, 17 y 17 Bis; Cap. III Ter | E7: Procedimiento escrito para integrar el expediente según el Grado de Riesgo, con los datos y documentos de los Anexos aplicables a tu fracción, verificación de identidad y cuestionario de conocimiento del Cliente. | F7: No | G7: Cumple | H7: =IF($G7="","",IF($G7="No aplica","",IF(OR($I7="",$J7=""),0,IFERROR(INDEX(PARAMETROS!$I$15:$I$18,MATCH($G7,PARAMETROS!$H$15:$H$18,0)),0)))) | I7: Manual, numeral 4.1 | J7: Expedientes íntegros con acuse de verificación de identificación oficial; muestreo trimestral firmado. | L7: =IF($G7="","Falta calificar esta obligación del Manual (Art. 37 Bis).",IF($G7="No aplica",IF($K7="","Exclusión sin constancia en el Manual: el Art. 37 Bis 2 exige hacerla constar por escrito.",""),IF($G7="No cumple","No cumple: puede actualizar una sanción (Art. 48 fr. IV). Llévalo al plan de acción de A8.",IF(OR($I7="",$J7=""),"Sin numeral del Manual o sin evidencia de aplicación efectiva: la obligación computa 0% (Art. 10 Septies 1, fr. III).",""))))
B8: II | C8: Mecanismos de clasificación de Riesgo | D8: Art. 23 Bis | E8: Modelo escrito que califique a cada Cliente en al menos tres grados, congruente con esta metodología, con reevaluación al menos cada seis meses (hoja B CLIENTE). | F8: No | G8: Cumple mayoritariamente | H8: =IF($G8="","",IF($G8="No aplica","",IF(OR($I8="",$J8=""),0,IFERROR(INDEX(PARAMETROS!$I$15:$I$18,MATCH($G8,PARAMETROS!$H$15:$H$18,0)),0)))) | I8: Manual, numeral 4.3 | J8: Cédulas de calificación de los 86 Clientes; falta evidenciar la reevaluación semestral de dos de ellos. | L8: =IF($G8="","Falta calificar esta obligación del Manual (Art. 37 Bis).",IF($G8="No aplica",IF($K8="","Exclusión sin constancia en el Manual: el Art. 37 Bis 2 exige hacerla constar por escrito.",""),IF($G8="No cumple","No cumple: puede actualizar una sanción (Art. 48 fr. IV). Llévalo al plan de acción de A8.",IF(OR($I8="",$J8=""),"Sin numeral del Manual o sin evidencia de aplicación efectiva: la obligación computa 0% (Art. 10 Septies 1, fr. III).",""))))
B9: III | C9: Medidas de debida diligencia aplicables conforme al Grado de Riesgo | D9: Arts. 17 y 17 Bis; Arts. 23 Ter 1 a 5 | E9: Regla explícita de qué expediente corresponde a cada grado: simplificado, completo del Art. 12, o reforzado con cuestionario y Firma Electrónica. | F9: No | G9: Cumple mayoritariamente | H9: =IF($G9="","",IF($G9="No aplica","",IF(OR($I9="",$J9=""),0,IFERROR(INDEX(PARAMETROS!$I$15:$I$18,MATCH($G9,PARAMETROS!$H$15:$H$18,0)),0)))) | I9: Manual, numeral 4.4 | J9: Matriz de correspondencia grado–expediente aplicada; dos expedientes reforzados sin acuse de Firma Electrónica. | L9: =IF($G9="","Falta calificar esta obligación del Manual (Art. 37 Bis).",IF($G9="No aplica",IF($K9="","Exclusión sin constancia en el Manual: el Art. 37 Bis 2 exige hacerla constar por escrito.",""),IF($G9="No cumple","No cumple: puede actualizar una sanción (Art. 48 fr. IV). Llévalo al plan de acción de A8.",IF(OR($I9="",$J9=""),"Sin numeral del Manual o sin evidencia de aplicación efectiva: la obligación computa 0% (Art. 10 Septies 1, fr. III).",""))))
B10: IV | C10: Identificación y seguimiento reforzado de Personas Políticamente Expuestas | D10: Arts. 23 Bis 3 y 23 Bis 4 | E10: Procedimiento de detección de PEP nacionales y extranjeras y de sus allegados, factores de Riesgo adicionales, y aprobación de un directivo para PEP extranjera de riesgo alto. | F10: No | G10: Cumple parcialmente | H10: =IF($G10="","",IF($G10="No aplica","",IF(OR($I10="",$J10=""),0,IFERROR(INDEX(PARAMETROS!$I$15:$I$18,MATCH($G10,PARAMETROS!$H$15:$H$18,0)),0)))) | I10: Manual, numeral 4.6 | J10: Se declara la búsqueda de PEP pero no se conserva la constancia por operación. | L10: =IF($G10="","Falta calificar esta obligación del Manual (Art. 37 Bis).",IF($G10="No aplica",IF($K10="","Exclusión sin constancia en el Manual: el Art. 37 Bis 2 exige hacerla constar por escrito.",""),IF($G10="No cumple","No cumple: puede actualizar una sanción (Art. 48 fr. IV). Llévalo al plan de acción de A8.",IF(OR($I10="",$J10=""),"Sin numeral del Manual o sin evidencia de aplicación efectiva: la obligación computa 0% (Art. 10 Septies 1, fr. III).",""))))
B11: V | C11: Detección de actos u operaciones que se apartan del Perfil transaccional | D11: Art. 41 fr. II | E11: Perfil transaccional documentado por Cliente y alertas por desviación, con bitácora de la alerta, su análisis y su conclusión. | F11: Condicionado | G11: Cumple parcialmente | H11: =IF($G11="","",IF($G11="No aplica","",IF(OR($I11="",$J11=""),0,IFERROR(INDEX(PARAMETROS!$I$15:$I$18,MATCH($G11,PARAMETROS!$H$15:$H$18,0)),0)))) | I11: Manual, numeral 6.4 | J11: Perfil transaccional documentado; las alertas se revisan sin bitácora de conclusión. | L11: =IF($G11="","Falta calificar esta obligación del Manual (Art. 37 Bis).",IF($G11="No aplica",IF($K11="","Exclusión sin constancia en el Manual: el Art. 37 Bis 2 exige hacerla constar por escrito.",""),IF($G11="No cumple","No cumple: puede actualizar una sanción (Art. 48 fr. IV). Llévalo al plan de acción de A8.",IF(OR($I11="",$J11=""),"Sin numeral del Manual o sin evidencia de aplicación efectiva: la obligación computa 0% (Art. 10 Septies 1, fr. III).",""))))
B12: VI | C12: Procedimientos para la presentación de Avisos e Informes | D12: Cap. V de las Reglas; Art. 23 de la Ley | E12: Flujo interno con responsable y plazos: Aviso ordinario a más tardar el día 17 del mes inmediato siguiente, y protocolo de 24 horas. | F12: No | G12: Cumple | H12: =IF($G12="","",IF($G12="No aplica","",IF(OR($I12="",$J12=""),0,IFERROR(INDEX(PARAMETROS!$I$15:$I$18,MATCH($G12,PARAMETROS!$H$15:$H$18,0)),0)))) | I12: Manual, numeral 5.2 | J12: Acuses del portal por los 14 Avisos del periodo, conciliados con el registro de operaciones. | L12: =IF($G12="","Falta calificar esta obligación del Manual (Art. 37 Bis).",IF($G12="No aplica",IF($K12="","Exclusión sin constancia en el Manual: el Art. 37 Bis 2 exige hacerla constar por escrito.",""),IF($G12="No cumple","No cumple: puede actualizar una sanción (Art. 48 fr. IV). Llévalo al plan de acción de A8.",IF(OR($I12="",$J12=""),"Sin numeral del Manual o sin evidencia de aplicación efectiva: la obligación computa 0% (Art. 10 Septies 1, fr. III).",""))))
B13: VII | C13: Mecanismos de conservación de información y documentación | D13: Art. 10 Septies 3, 3er párr.; Art. 41 fr. I y IV | E13: Política de resguardo por diez años, lugar y medio de conservación, y medidas de seguridad contra pérdida, alteración u ocultamiento. | F13: No | G13: Cumple | H13: =IF($G13="","",IF($G13="No aplica","",IF(OR($I13="",$J13=""),0,IFERROR(INDEX(PARAMETROS!$I$15:$I$18,MATCH($G13,PARAMETROS!$H$15:$H$18,0)),0)))) | I13: Manual, numeral 8.1 | J13: Política de resguardo firmada, respaldo cifrado y control de acceso al repositorio. | L13: =IF($G13="","Falta calificar esta obligación del Manual (Art. 37 Bis).",IF($G13="No aplica",IF($K13="","Exclusión sin constancia en el Manual: el Art. 37 Bis 2 exige hacerla constar por escrito.",""),IF($G13="No cumple","No cumple: puede actualizar una sanción (Art. 48 fr. IV). Llévalo al plan de acción de A8.",IF(OR($I13="",$J13=""),"Sin numeral del Manual o sin evidencia de aplicación efectiva: la obligación computa 0% (Art. 10 Septies 1, fr. III).",""))))
B14: VIII | C14: Seguimiento y acumulación de actos u operaciones frente a los umbrales | D14: Art. 17, penúltimo párr. de la Ley; Art. 41 fr. II | E14: Mecanismo que agrupe las operaciones del mismo Cliente y dispare el Aviso cuando la suma acumulada alcance el umbral de tu fracción. | F14: Condicionado | G14: Cumple mayoritariamente | H14: =IF($G14="","",IF($G14="No aplica","",IF(OR($I14="",$J14=""),0,IFERROR(INDEX(PARAMETROS!$I$15:$I$18,MATCH($G14,PARAMETROS!$H$15:$H$18,0)),0)))) | I14: Manual, numeral 5.4 | J14: Reporte de acumulación del sistema; falta prueba de recorrido de un caso completo. | L14: =IF($G14="","Falta calificar esta obligación del Manual (Art. 37 Bis).",IF($G14="No aplica",IF($K14="","Exclusión sin constancia en el Manual: el Art. 37 Bis 2 exige hacerla constar por escrito.",""),IF($G14="No cumple","No cumple: puede actualizar una sanción (Art. 48 fr. IV). Llévalo al plan de acción de A8.",IF(OR($I14="",$J14=""),"Sin numeral del Manual o sin evidencia de aplicación efectiva: la obligación computa 0% (Art. 10 Septies 1, fr. III).",""))))
B15: IX | C15: Identificación de personas publicadas en listas de autoridades nacionales u organismos internacionales | D15: Arts. 38 y 41 fr. V | E15: Búsqueda documentada del Cliente, su Beneficiario Controlador y sus apoderados contra las listas aplicables, con constancia por operación y protocolo ante coincidencia. | F15: No | G15: Cumple | H15: =IF($G15="","",IF($G15="No aplica","",IF(OR($I15="",$J15=""),0,IFERROR(INDEX(PARAMETROS!$I$15:$I$18,MATCH($G15,PARAMETROS!$H$15:$H$18,0)),0)))) | I15: Manual, numeral 6.2 | J15: Bitácora de validación contra listas con acuse por operación en el expediente electrónico. | L15: =IF($G15="","Falta calificar esta obligación del Manual (Art. 37 Bis).",IF($G15="No aplica",IF($K15="","Exclusión sin constancia en el Manual: el Art. 37 Bis 2 exige hacerla constar por escrito.",""),IF($G15="No cumple","No cumple: puede actualizar una sanción (Art. 48 fr. IV). Llévalo al plan de acción de A8.",IF(OR($I15="",$J15=""),"Sin numeral del Manual o sin evidencia de aplicación efectiva: la obligación computa 0% (Art. 10 Septies 1, fr. III).",""))))
B16: X | C16: Funciones y responsabilidades de la persona Representante Encargada de Cumplimiento | D16: Art. 20 de la Ley | E16: Designación vigente y acreditada ante el SAT, con funciones, nivel de autoridad y suplencia definidos por escrito. | F16: Condicionado | G16: Cumple | H16: =IF($G16="","",IF($G16="No aplica","",IF(OR($I16="",$J16=""),0,IFERROR(INDEX(PARAMETROS!$I$15:$I$18,MATCH($G16,PARAMETROS!$H$15:$H$18,0)),0)))) | I16: Manual, numeral 3.1 | J16: Constancia de alta de la Representante Encargada de Cumplimiento y descripción de funciones firmada. | L16: =IF($G16="","Falta calificar esta obligación del Manual (Art. 37 Bis).",IF($G16="No aplica",IF($K16="","Exclusión sin constancia en el Manual: el Art. 37 Bis 2 exige hacerla constar por escrito.",""),IF($G16="No cumple","No cumple: puede actualizar una sanción (Art. 48 fr. IV). Llévalo al plan de acción de A8.",IF(OR($I16="",$J16=""),"Sin numeral del Manual o sin evidencia de aplicación efectiva: la obligación computa 0% (Art. 10 Septies 1, fr. III).",""))))
B17: XI | C17: Programas de capacitación | D17: Cap. XII, Art. 39 Bis | E17: Programa anual con contenido, destinatarios (órgano de administración, directivos, personal de atención, de envío de Avisos y de auditoría) y constancias de acreditación. | F17: No | G17: Cumple mayoritariamente | H17: =IF($G17="","",IF($G17="No aplica","",IF(OR($I17="",$J17=""),0,IFERROR(INDEX(PARAMETROS!$I$15:$I$18,MATCH($G17,PARAMETROS!$H$15:$H$18,0)),0)))) | I17: Manual, numeral 9.1 | J17: Constancias de capacitación 2026 del 82% del personal objetivo. | L17: =IF($G17="","Falta calificar esta obligación del Manual (Art. 37 Bis).",IF($G17="No aplica",IF($K17="","Exclusión sin constancia en el Manual: el Art. 37 Bis 2 exige hacerla constar por escrito.",""),IF($G17="No cumple","No cumple: puede actualizar una sanción (Art. 48 fr. IV). Llévalo al plan de acción de A8.",IF(OR($I17="",$J17=""),"Sin numeral del Manual o sin evidencia de aplicación efectiva: la obligación computa 0% (Art. 10 Septies 1, fr. III).",""))))
B18: XII | C18: Mecanismos de control interno, supervisión y auditoría | D18: Cap. XIV, Arts. 42 a 51 | E18: Programa de revisión anual y designación de quien emite el dictamen: puede ser el área interna si tu riesgo es bajo o medio (Art. 44); auditor externo certificado por la UIF si es alto, o si así lo eliges (Art. 45). Ver A6. | F18: No | G18: Cumple parcialmente | H18: =IF($G18="","",IF($G18="No aplica","",IF(OR($I18="",$J18=""),0,IFERROR(INDEX(PARAMETROS!$I$15:$I$18,MATCH($G18,PARAMETROS!$H$15:$H$18,0)),0)))) | I18: Manual, numeral 10.1 | J18: Programa de auditoría aprobado; primer dictamen aún no exigible (primer periodo: 2028). | L18: =IF($G18="","Falta calificar esta obligación del Manual (Art. 37 Bis).",IF($G18="No aplica",IF($K18="","Exclusión sin constancia en el Manual: el Art. 37 Bis 2 exige hacerla constar por escrito.",""),IF($G18="No cumple","No cumple: puede actualizar una sanción (Art. 48 fr. IV). Llévalo al plan de acción de A8.",IF(OR($I18="",$J18=""),"Sin numeral del Manual o sin evidencia de aplicación efectiva: la obligación computa 0% (Art. 10 Septies 1, fr. III).",""))))
... B20: XIV | C20: Procedimientos para la actualización del propio Manual de Políticas Internas | D20: Art. 37 Bis 3 | E20: Procedimiento y periodicidad de actualización, responsable, control de versiones y atención a los ajustes que señale el SAT. | F20: No | G20: Cumple mayoritariamente | H20: =IF($G20="","",IF($G20="No aplica","",IF(OR($I20="",$J20=""),0,IFERROR(INDEX(PARAMETROS!$I$15:$I$18,MATCH($G20,PARAMETROS!$H$15:$H$18,0)),0)))) | I20: Manual, numeral 12.1 | J20: Control de versiones del Manual; falta fijar la periodicidad mínima de revisión. | L20: =IF($G20="","Falta calificar esta obligación del Manual (Art. 37 Bis).",IF($G20="No aplica",IF($K20="","Exclusión sin constancia en el Manual: el Art. 37 Bis 2 exige hacerla constar por escrito.",""),IF($G20="No cumple","No cumple: puede actualizar una sanción (Art. 48 fr. IV). Llévalo al plan de acción de A8.",IF(OR($I20="",$J20=""),"Sin numeral del Manual o sin evidencia de aplicación efectiva: la obligación computa 0% (Art. 10 Septies 1, fr. III).",""))))
B23: RESULTADO DEL CATÁLOGO — ESTA ES LA MITIGACIÓN DE TODA LA MATRIZ
B24: Obligaciones del catálogo (Art. 37 Bis): | F24: =COUNTA($B$7:$B$20)
B25: Excluidas por «No aplica» (Art. 37 Bis 2): | F25: =COUNTIF($G$7:$G$20,"No aplica")
B26: Obligaciones exigibles — denominador: | F26: =$F$24-$F$25
B27: Suma de los porcentajes obtenidos: | F27: =SUM($H$7:$H$20)
B28: EFECTIVIDAD DE LOS MITIGANTES: | F28: =IFERROR($F$27/$F$26,0)
B29: Tope máximo de reducción (PARÁMETROS C30): | F29: =PARAMETROS!$C$30
B30: REDUCCIÓN QUE SE APLICARÁ AL RIESGO INHERENTE: | F30: =$F$28*$F$29
B32: ALERTAS DEL CATÁLOGO
B33: Obligaciones en «No cumple»: | F33: =COUNTIF($G$7:$G$20,"No cumple")
B34: Exclusiones sin constancia en el Manual: | F34: =SUMPRODUCT(--($G$7:$G$20="No aplica"),--($K$7:$K$20=""))
B35: Obligaciones sin numeral del Manual o sin evidencia: | F35: =SUMPRODUCT(--($G$7:$G$20<>""),--($G$7:$G$20<>"No aplica"),--((($I$7:$I$20="")+($J$7:$J$20=""))>0))
B36: Obligaciones sin calificar: | F36: =COUNTBLANK($G$7:$G$20)
B38: =IF($F$33>0,"Hay "&$F$33&" obligación(es) en «No cumple». El Art. 48 fr. IV las define como incumplimiento que puede actualizar una sanción: no basta con que bajen el promedio, deben ir al plan de acción de A8.",IF($F$36>0,"Faltan "&$F$36&" obligación(es) por calificar. Mientras no las califiques computan 0% y tu residual sale más alto de lo real.","Catálogo completo: las 14 obligaciones están calificadas y ninguna está en «No cumple»."))
B40: Cómo se calcula: Efectividad = suma de los porcentajes ÷ obligaciones exigibles. El denominador es fijo (14) y solo baja cuando una obligación es «No aplica». Por eso registrar menos controles ya NO mejora el resultado: lo empeora.
B41: El Art. 37 Bis 2 no enlista fracciones: exenta cualquier contenido del Manual referido a actos u operaciones que se determine no realizar, con constancia en el propio Manual. Que en esta matriz sólo se habilite «No aplica» en las fracciones V, VIII y X es criterio de la herramienta, y de forma condicionada: V para quien opera exclusivamente con Clientes ocasionales sin Relación de Negocios; VIII para las fracciones cuyo umbral no admite acumulación; X para la persona física que realiza la Actividad Vulnerable sin estructura, porque el Art. 20 de la Ley ata la designación a las personas morales. Las otras once no admiten exclusión.
B42: El Art. 48 fr. V exige que el auditor verifique que la exclusión no actualice un incumplimiento y que sea consistente con el análisis de Riesgos. Por eso la justificación pide el numeral del Manual donde consta la exención, no un texto libre.
B43: Una obligación cubierta en el papel pero sin evidencia de aplicación efectiva computa 0%: el Art. 10 Septies 1, fr. III habla de los mitigantes «así como su efectiva aplicación». Control diseñado, control implementado y control operando son tres estados distintos y se prueban distinto.
B44: Pendiente declarado: la columna «Qué se espera» es todavía guía común a las 30 fracciones. El anexo sectorial —qué se espera en cada obligación según tu Actividad Vulnerable— es el siguiente entregable y no altera el denominador ni el cálculo.

Sheet A4 BIS ADICIONALES
B2: A4 BIS · CONTROLES ADICIONALES (por encima del mínimo) — INFORMATIVO
B3: Registra aquí los controles que tienes por encima de las 14 obligaciones del catálogo. Esta hoja NO cambia el resultado: la mitigación se calcula en A4 CONTROLES MINIMOS. Sirve para documentar tu programa completo ante un requerimiento sin alterar el número.
B4: Complemento del paso 6 · No entra en el cálculo · Sigue: A5 RESIDUAL
B6: # | C6: Descripción del control | D6: Elemento que mitiga (informativo) | E6: Naturaleza | F6: Automatización | G6: Frecuencia | H6: Efectividad | I6: Efectividad % | J6: Numeral del Manual que lo prevé | K6: Evidencia de aplicación efectiva y dónde se resguarda | L6: Aviso
B7: 1 | C7: El sistema valida a cada Cliente, a su Beneficiario Controlador y a los apoderados contra la lista de personas bloqueadas del Art. 38 y las listas internacionales, en cada operación y no sólo al alta. | D7: 2 | E7: Preventivo | F7: Automático | G7: Permanente | H7: Cumple | I7: =IF($H7="","",IF(OR($J7="",$K7=""),0,IFERROR(INDEX(PARAMETROS!$I$15:$I$18,MATCH($H7,PARAMETROS!$H$15:$H$18,0)),0))) | J7: Manual, numeral 6.2 | K7: Bitácora de validación con acuse por operación; 112 corridas conciliadas contra el número de operaciones del periodo. | L7: =IF($H7="","",IF(OR($J7="",$K7=""),"Sin numeral del Manual o sin evidencia: el mitigante no acredita aplicación efectiva (Art. 10 Septies 1, fr. III).",""))
B8: 2 | C8: Política de aceptación de efectivo con umbral interno de 150,000 pesos por operación, por debajo del umbral de aviso, con validación del origen y autorización escrita de la Encargada de Cumplimiento por encima de ese monto. | D8: 4 | E8: Preventivo | F8: Semiautomático | G8: Permanente | H8: Cumple mayoritariamente | I8: =IF($H8="","",IF(OR($J8="",$K8=""),0,IFERROR(INDEX(PARAMETROS!$I$15:$I$18,MATCH($H8,PARAMETROS!$H$15:$H$18,0)),0))) | J8: Manual, numeral 7.1 | K8: Reporte mensual de excepciones firmado; faltan las autorizaciones de dos operaciones de mayo de 2026. | L8: =IF($H8="","",IF(OR($J8="",$K8=""),"Sin numeral del Manual o sin evidencia: el mitigante no acredita aplicación efectiva (Art. 10 Septies 1, fr. III).",""))
B9: 3 | C9: Verificación de la constitución y del objeto social de toda persona moral compradora en el registro electrónico de la Secretaría de Economía, antes de la firma. | D9: 2 | E9: Preventivo | F9: Manual | G9: Permanente | H9: Cumple | I9: =IF($H9="","",IF(OR($J9="",$K9=""),0,IFERROR(INDEX(PARAMETROS!$I$15:$I$18,MATCH($H9,PARAMETROS!$H$15:$H$18,0)),0))) | J9: Manual, numeral 4.2 | K9: Impresión del folio electrónico mercantil integrada a los 31 expedientes de persona moral del periodo. | L9: =IF($H9="","",IF(OR($J9="",$K9=""),"Sin numeral del Manual o sin evidencia: el mitigante no acredita aplicación efectiva (Art. 10 Septies 1, fr. III).",""))
B10: 4 | C10: Regla de cuatro ojos: ninguna operación que supere el umbral de aviso se firma sin visto bueno documentado de la Encargada de Cumplimiento, además del ejecutivo de venta. | D10: 1 | E10: Preventivo | F10: Manual | G10: Permanente | H10: Cumple | I10: =IF($H10="","",IF(OR($J10="",$K10=""),0,IFERROR(INDEX(PARAMETROS!$I$15:$I$18,MATCH($H10,PARAMETROS!$H$15:$H$18,0)),0))) | J10: Manual, numeral 5.1 | K10: Cédula de doble firma en las 47 operaciones del periodo que superaron el umbral. | L10: =IF($H10="","",IF(OR($J10="",$K10=""),"Sin numeral del Manual o sin evidencia: el mitigante no acredita aplicación efectiva (Art. 10 Septies 1, fr. III).",""))
B11: 5 | C11: Alerta automática cuando el pago proviene de un tercero distinto del comprador o de una cuenta no declarada en el expediente. | D11: 4 | E11: Detectivo | F11: Automático | G11: Permanente | H11: Cumple mayoritariamente | I11: =IF($H11="","",IF(OR($J11="",$K11=""),0,IFERROR(INDEX(PARAMETROS!$I$15:$I$18,MATCH($H11,PARAMETROS!$H$15:$H$18,0)),0))) | J11: Manual, numeral 6.4 | K11: Se dispararon 7 alertas en el periodo; 5 tienen dictamen documentado y 2 siguen en análisis. | L11: =IF($H11="","",IF(OR($J11="",$K11=""),"Sin numeral del Manual o sin evidencia: el mitigante no acredita aplicación efectiva (Art. 10 Septies 1, fr. III).",""))
B12: 6 | C12: Capacitación específica de fuerza de ventas sobre señales de alerta en preventa, adicional al programa anual obligatorio. | D12: 2 | E12: Preventivo | F12: Manual | G12: Periódico | H12: Cumple mayoritariamente | I12: =IF($H12="","",IF(OR($J12="",$K12=""),0,IFERROR(INDEX(PARAMETROS!$I$15:$I$18,MATCH($H12,PARAMETROS!$H$15:$H$18,0)),0))) | J12: Manual, numeral 9.2 | K12: Lista de asistencia de la sesión de marzo de 2026; cubrió a 9 de los 11 ejecutivos. | L12: =IF($H12="","",IF(OR($J12="",$K12=""),"Sin numeral del Manual o sin evidencia: el mitigante no acredita aplicación efectiva (Art. 10 Septies 1, fr. III).",""))
B13: 7 | I13: =IF($H13="","",IF(OR($J13="",$K13=""),0,IFERROR(INDEX(PARAMETROS!$I$15:$I$18,MATCH($H13,PARAMETROS!$H$15:$H$18,0)),0))) | L13: =IF($H13="","",IF(OR($J13="",$K13=""),"Sin numeral del Manual o sin evidencia: el mitigante no acredita aplicación efectiva (Art. 10 Septies 1, fr. III).",""))
B14: 8 | I14: =IF($H14="","",IF(OR($J14="",$K14=""),0,IFERROR(INDEX(PARAMETROS!$I$15:$I$18,MATCH($H14,PARAMETROS!$H$15:$H$18,0)),0))) | L14: =IF($H14="","",IF(OR($J14="",$K14=""),"Sin numeral del Manual o sin evidencia: el mitigante no acredita aplicación efectiva (Art. 10 Septies 1, fr. III).",""))
B15: 9 | I15: =IF($H15="","",IF(OR($J15="",$K15=""),0,IFERROR(INDEX(PARAMETROS!$I$15:$I$18,MATCH($H15,PARAMETROS!$H$15:$H$18,0)),0))) | L15: =IF($H15="","",IF(OR($J15="",$K15=""),"Sin numeral del Manual o sin evidencia: el mitigante no acredita aplicación efectiva (Art. 10 Septies 1, fr. III).",""))
B16: 10 | I16: =IF($H16="","",IF(OR($J16="",$K16=""),0,IFERROR(INDEX(PARAMETROS!$I$15:$I$18,MATCH($H16,PARAMETROS!$H$15:$H$18,0)),0))) | L16: =IF($H16="","",IF(OR($J16="",$K16=""),"Sin numeral del Manual o sin evidencia: el mitigante no acredita aplicación efectiva (Art. 10 Septies 1, fr. III).",""))
B17: 11 | I17: =IF($H17="","",IF(OR($J17="",$K17=""),0,IFERROR(INDEX(PARAMETROS!$I$15:$I$18,MATCH($H17,PARAMETROS!$H$15:$H$18,0)),0))) | L17: =IF($H17="","",IF(OR($J17="",$K17=""),"Sin numeral del Manual o sin evidencia: el mitigante no acredita aplicación efectiva (Art. 10 Septies 1, fr. III).",""))
B18: 12 | I18: =IF($H18="","",IF(OR($J18="",$K18=""),0,IFERROR(INDEX(PARAMETROS!$I$15:$I$18,MATCH($H18,PARAMETROS!$H$15:$H$18,0)),0))) | L18: =IF($H18="","",IF(OR($J18="",$K18=""),"Sin numeral del Manual o sin evidencia: el mitigante no acredita aplicación efectiva (Art. 10 Septies 1, fr. III).",""))
